[14/Mar/2024 16:07:48] INFO [django.utils.autoreload:668] Watching for file changes with StatReloader
[14/Mar/2024 16:08:20] INFO [django.utils.autoreload:668] Watching for file changes with StatReloader
[14/Mar/2024 16:08:58] INFO [django.utils.autoreload:266] /home/rashid/Projects/CropGnosis/config/settings.py changed, reloading.
[15/Mar/2024 05:50:58] WARNING [django.request:241] Not Found: /
[15/Mar/2024 05:52:19] WARNING [django.request:241] Unauthorized: /api/auth/customer/login
[15/Mar/2024 05:53:39] WARNING [django.request:241] Bad Request: /api/auth/customer/address
[15/Mar/2024 06:12:05] WARNING [django.request:241] Unauthorized: /api/auth/mentor/login
[15/Mar/2024 06:13:09] WARNING [django.request:241] Unauthorized: /api/auth/mentor/login
[15/Mar/2024 06:13:18] WARNING [django.request:241] Unauthorized: /api/auth/mentor/login
[15/Mar/2024 06:13:52] WARNING [django.request:241] Unauthorized: /api/auth/mentor/login
[15/Mar/2024 06:13:57] WARNING [django.request:241] Unauthorized: /api/auth/mentor/login
[15/Mar/2024 06:16:57] WARNING [django.request:241] Forbidden: /api/auth/mentor/login
[15/Mar/2024 06:17:27] WARNING [django.request:241] Forbidden: /api/auth/mentor/login
[15/Mar/2024 06:17:36] WARNING [django.request:241] Forbidden: /api/auth/mentor/login
[15/Mar/2024 06:17:46] WARNING [django.request:241] Forbidden: /api/auth/mentor/login
[15/Mar/2024 06:28:08] WARNING [django.request:241] Unauthorized: /api/auth/mentor/update-address
[15/Mar/2024 06:28:32] WARNING [django.request:241] Method Not Allowed: /api/auth/mentor/update-address
[15/Mar/2024 06:29:03] ERROR [django.request:241] Internal Server Error: /api/auth/mentor/update-address
Traceback (most recent call last):
  File "/home/rashid/.cache/pypoetry/virtualenvs/cropgnosis-irOgLtvg-py3.10/lib/python3.10/site-packages/django/core/handlers/exception.py", line 55, in inner
    response = get_response(request)
  File "/home/rashid/.cache/pypoetry/virtualenvs/cropgnosis-irOgLtvg-py3.10/lib/python3.10/site-packages/django/core/handlers/base.py", line 197, in _get_response
    response = wrapped_callback(request, *callback_args, **callback_kwargs)
  File "/home/rashid/.cache/pypoetry/virtualenvs/cropgnosis-irOgLtvg-py3.10/lib/python3.10/site-packages/django/views/decorators/csrf.py", line 65, in _view_wrapper
    return view_func(request, *args, **kwargs)
  File "/home/rashid/.cache/pypoetry/virtualenvs/cropgnosis-irOgLtvg-py3.10/lib/python3.10/site-packages/django/views/generic/base.py", line 104, in view
    return self.dispatch(request, *args, **kwargs)
  File "/home/rashid/.cache/pypoetry/virtualenvs/cropgnosis-irOgLtvg-py3.10/lib/python3.10/site-packages/rest_framework/views.py", line 509, in dispatch
    response = self.handle_exception(exc)
  File "/home/rashid/.cache/pypoetry/virtualenvs/cropgnosis-irOgLtvg-py3.10/lib/python3.10/site-packages/rest_framework/views.py", line 469, in handle_exception
    self.raise_uncaught_exception(exc)
  File "/home/rashid/.cache/pypoetry/virtualenvs/cropgnosis-irOgLtvg-py3.10/lib/python3.10/site-packages/rest_framework/views.py", line 480, in raise_uncaught_exception
    raise exc
  File "/home/rashid/.cache/pypoetry/virtualenvs/cropgnosis-irOgLtvg-py3.10/lib/python3.10/site-packages/rest_framework/views.py", line 506, in dispatch
    response = handler(request, *args, **kwargs)
  File "/home/rashid/Projects/CropGnosis/apps/authorization/views/mentor_view.py", line 92, in patch
    address = account.my_addresses.all().last()
AttributeError: 'Address' object has no attribute 'all'
[15/Mar/2024 06:31:57] WARNING [django.request:241] Unauthorized: /api/auth/mentor/address
[15/Mar/2024 06:32:22] ERROR [django.request:241] Internal Server Error: /api/auth/mentor/address
Traceback (most recent call last):
  File "/home/rashid/.cache/pypoetry/virtualenvs/cropgnosis-irOgLtvg-py3.10/lib/python3.10/site-packages/django/core/handlers/exception.py", line 55, in inner
    response = get_response(request)
  File "/home/rashid/.cache/pypoetry/virtualenvs/cropgnosis-irOgLtvg-py3.10/lib/python3.10/site-packages/django/core/handlers/base.py", line 197, in _get_response
    response = wrapped_callback(request, *callback_args, **callback_kwargs)
  File "/home/rashid/.cache/pypoetry/virtualenvs/cropgnosis-irOgLtvg-py3.10/lib/python3.10/site-packages/django/views/decorators/csrf.py", line 65, in _view_wrapper
    return view_func(request, *args, **kwargs)
  File "/home/rashid/.cache/pypoetry/virtualenvs/cropgnosis-irOgLtvg-py3.10/lib/python3.10/site-packages/django/views/generic/base.py", line 104, in view
    return self.dispatch(request, *args, **kwargs)
  File "/home/rashid/.cache/pypoetry/virtualenvs/cropgnosis-irOgLtvg-py3.10/lib/python3.10/site-packages/rest_framework/views.py", line 509, in dispatch
    response = self.handle_exception(exc)
  File "/home/rashid/.cache/pypoetry/virtualenvs/cropgnosis-irOgLtvg-py3.10/lib/python3.10/site-packages/rest_framework/views.py", line 469, in handle_exception
    self.raise_uncaught_exception(exc)
  File "/home/rashid/.cache/pypoetry/virtualenvs/cropgnosis-irOgLtvg-py3.10/lib/python3.10/site-packages/rest_framework/views.py", line 480, in raise_uncaught_exception
    raise exc
  File "/home/rashid/.cache/pypoetry/virtualenvs/cropgnosis-irOgLtvg-py3.10/lib/python3.10/site-packages/rest_framework/views.py", line 506, in dispatch
    response = handler(request, *args, **kwargs)
  File "/home/rashid/Projects/CropGnosis/apps/authorization/views/mentor_view.py", line 86, in get
    serializer = self.serializer_classr(request.user)
AttributeError: 'MentorAccountAddress' object has no attribute 'serializer_classr'
[15/Mar/2024 06:32:49] ERROR [django.request:241] Internal Server Error: /api/auth/mentor/address
Traceback (most recent call last):
  File "/home/rashid/.cache/pypoetry/virtualenvs/cropgnosis-irOgLtvg-py3.10/lib/python3.10/site-packages/django/core/handlers/exception.py", line 55, in inner
    response = get_response(request)
  File "/home/rashid/.cache/pypoetry/virtualenvs/cropgnosis-irOgLtvg-py3.10/lib/python3.10/site-packages/django/core/handlers/base.py", line 197, in _get_response
    response = wrapped_callback(request, *callback_args, **callback_kwargs)
  File "/home/rashid/.cache/pypoetry/virtualenvs/cropgnosis-irOgLtvg-py3.10/lib/python3.10/site-packages/django/views/decorators/csrf.py", line 65, in _view_wrapper
    return view_func(request, *args, **kwargs)
  File "/home/rashid/.cache/pypoetry/virtualenvs/cropgnosis-irOgLtvg-py3.10/lib/python3.10/site-packages/django/views/generic/base.py", line 104, in view
    return self.dispatch(request, *args, **kwargs)
  File "/home/rashid/.cache/pypoetry/virtualenvs/cropgnosis-irOgLtvg-py3.10/lib/python3.10/site-packages/rest_framework/views.py", line 509, in dispatch
    response = self.handle_exception(exc)
  File "/home/rashid/.cache/pypoetry/virtualenvs/cropgnosis-irOgLtvg-py3.10/lib/python3.10/site-packages/rest_framework/views.py", line 469, in handle_exception
    self.raise_uncaught_exception(exc)
  File "/home/rashid/.cache/pypoetry/virtualenvs/cropgnosis-irOgLtvg-py3.10/lib/python3.10/site-packages/rest_framework/views.py", line 480, in raise_uncaught_exception
    raise exc
  File "/home/rashid/.cache/pypoetry/virtualenvs/cropgnosis-irOgLtvg-py3.10/lib/python3.10/site-packages/rest_framework/views.py", line 506, in dispatch
    response = handler(request, *args, **kwargs)
  File "/home/rashid/Projects/CropGnosis/apps/authorization/views/mentor_view.py", line 87, in get
    return Response(serializer.user)
AttributeError: 'MentorAddressSerializer' object has no attribute 'user'
