[14/Mar/2024 16:07:48] INFO [django.utils.autoreload:668] Watching for file changes with StatReloader
[14/Mar/2024 16:08:20] INFO [django.utils.autoreload:668] Watching for file changes with StatReloader
[14/Mar/2024 16:08:58] INFO [django.utils.autoreload:266] /home/rashid/Projects/CropGnosis/config/settings.py changed, reloading.
[15/Mar/2024 05:50:58] WARNING [django.request:241] Not Found: /
[15/Mar/2024 05:52:19] WARNING [django.request:241] Unauthorized: /api/auth/customer/login
[15/Mar/2024 05:53:39] WARNING [django.request:241] Bad Request: /api/auth/customer/address
[15/Mar/2024 06:12:05] WARNING [django.request:241] Unauthorized: /api/auth/mentor/login
[15/Mar/2024 06:13:09] WARNING [django.request:241] Unauthorized: /api/auth/mentor/login
[15/Mar/2024 06:13:18] WARNING [django.request:241] Unauthorized: /api/auth/mentor/login
[15/Mar/2024 06:13:52] WARNING [django.request:241] Unauthorized: /api/auth/mentor/login
[15/Mar/2024 06:13:57] WARNING [django.request:241] Unauthorized: /api/auth/mentor/login
[15/Mar/2024 06:16:57] WARNING [django.request:241] Forbidden: /api/auth/mentor/login
[15/Mar/2024 06:17:27] WARNING [django.request:241] Forbidden: /api/auth/mentor/login
[15/Mar/2024 06:17:36] WARNING [django.request:241] Forbidden: /api/auth/mentor/login
[15/Mar/2024 06:17:46] WARNING [django.request:241] Forbidden: /api/auth/mentor/login
[15/Mar/2024 06:28:08] WARNING [django.request:241] Unauthorized: /api/auth/mentor/update-address
[15/Mar/2024 06:28:32] WARNING [django.request:241] Method Not Allowed: /api/auth/mentor/update-address
[15/Mar/2024 06:29:03] ERROR [django.request:241] Internal Server Error: /api/auth/mentor/update-address
Traceback (most recent call last):
  File "/home/rashid/.cache/pypoetry/virtualenvs/cropgnosis-irOgLtvg-py3.10/lib/python3.10/site-packages/django/core/handlers/exception.py", line 55, in inner
    response = get_response(request)
  File "/home/rashid/.cache/pypoetry/virtualenvs/cropgnosis-irOgLtvg-py3.10/lib/python3.10/site-packages/django/core/handlers/base.py", line 197, in _get_response
    response = wrapped_callback(request, *callback_args, **callback_kwargs)
  File "/home/rashid/.cache/pypoetry/virtualenvs/cropgnosis-irOgLtvg-py3.10/lib/python3.10/site-packages/django/views/decorators/csrf.py", line 65, in _view_wrapper
    return view_func(request, *args, **kwargs)
  File "/home/rashid/.cache/pypoetry/virtualenvs/cropgnosis-irOgLtvg-py3.10/lib/python3.10/site-packages/django/views/generic/base.py", line 104, in view
    return self.dispatch(request, *args, **kwargs)
  File "/home/rashid/.cache/pypoetry/virtualenvs/cropgnosis-irOgLtvg-py3.10/lib/python3.10/site-packages/rest_framework/views.py", line 509, in dispatch
    response = self.handle_exception(exc)
  File "/home/rashid/.cache/pypoetry/virtualenvs/cropgnosis-irOgLtvg-py3.10/lib/python3.10/site-packages/rest_framework/views.py", line 469, in handle_exception
    self.raise_uncaught_exception(exc)
  File "/home/rashid/.cache/pypoetry/virtualenvs/cropgnosis-irOgLtvg-py3.10/lib/python3.10/site-packages/rest_framework/views.py", line 480, in raise_uncaught_exception
    raise exc
  File "/home/rashid/.cache/pypoetry/virtualenvs/cropgnosis-irOgLtvg-py3.10/lib/python3.10/site-packages/rest_framework/views.py", line 506, in dispatch
    response = handler(request, *args, **kwargs)
  File "/home/rashid/Projects/CropGnosis/apps/authorization/views/mentor_view.py", line 92, in patch
    address = account.my_addresses.all().last()
AttributeError: 'Address' object has no attribute 'all'
[15/Mar/2024 06:31:57] WARNING [django.request:241] Unauthorized: /api/auth/mentor/address
[15/Mar/2024 06:32:22] ERROR [django.request:241] Internal Server Error: /api/auth/mentor/address
Traceback (most recent call last):
  File "/home/rashid/.cache/pypoetry/virtualenvs/cropgnosis-irOgLtvg-py3.10/lib/python3.10/site-packages/django/core/handlers/exception.py", line 55, in inner
    response = get_response(request)
  File "/home/rashid/.cache/pypoetry/virtualenvs/cropgnosis-irOgLtvg-py3.10/lib/python3.10/site-packages/django/core/handlers/base.py", line 197, in _get_response
    response = wrapped_callback(request, *callback_args, **callback_kwargs)
  File "/home/rashid/.cache/pypoetry/virtualenvs/cropgnosis-irOgLtvg-py3.10/lib/python3.10/site-packages/django/views/decorators/csrf.py", line 65, in _view_wrapper
    return view_func(request, *args, **kwargs)
  File "/home/rashid/.cache/pypoetry/virtualenvs/cropgnosis-irOgLtvg-py3.10/lib/python3.10/site-packages/django/views/generic/base.py", line 104, in view
    return self.dispatch(request, *args, **kwargs)
  File "/home/rashid/.cache/pypoetry/virtualenvs/cropgnosis-irOgLtvg-py3.10/lib/python3.10/site-packages/rest_framework/views.py", line 509, in dispatch
    response = self.handle_exception(exc)
  File "/home/rashid/.cache/pypoetry/virtualenvs/cropgnosis-irOgLtvg-py3.10/lib/python3.10/site-packages/rest_framework/views.py", line 469, in handle_exception
    self.raise_uncaught_exception(exc)
  File "/home/rashid/.cache/pypoetry/virtualenvs/cropgnosis-irOgLtvg-py3.10/lib/python3.10/site-packages/rest_framework/views.py", line 480, in raise_uncaught_exception
    raise exc
  File "/home/rashid/.cache/pypoetry/virtualenvs/cropgnosis-irOgLtvg-py3.10/lib/python3.10/site-packages/rest_framework/views.py", line 506, in dispatch
    response = handler(request, *args, **kwargs)
  File "/home/rashid/Projects/CropGnosis/apps/authorization/views/mentor_view.py", line 86, in get
    serializer = self.serializer_classr(request.user)
AttributeError: 'MentorAccountAddress' object has no attribute 'serializer_classr'
[15/Mar/2024 06:32:49] ERROR [django.request:241] Internal Server Error: /api/auth/mentor/address
Traceback (most recent call last):
  File "/home/rashid/.cache/pypoetry/virtualenvs/cropgnosis-irOgLtvg-py3.10/lib/python3.10/site-packages/django/core/handlers/exception.py", line 55, in inner
    response = get_response(request)
  File "/home/rashid/.cache/pypoetry/virtualenvs/cropgnosis-irOgLtvg-py3.10/lib/python3.10/site-packages/django/core/handlers/base.py", line 197, in _get_response
    response = wrapped_callback(request, *callback_args, **callback_kwargs)
  File "/home/rashid/.cache/pypoetry/virtualenvs/cropgnosis-irOgLtvg-py3.10/lib/python3.10/site-packages/django/views/decorators/csrf.py", line 65, in _view_wrapper
    return view_func(request, *args, **kwargs)
  File "/home/rashid/.cache/pypoetry/virtualenvs/cropgnosis-irOgLtvg-py3.10/lib/python3.10/site-packages/django/views/generic/base.py", line 104, in view
    return self.dispatch(request, *args, **kwargs)
  File "/home/rashid/.cache/pypoetry/virtualenvs/cropgnosis-irOgLtvg-py3.10/lib/python3.10/site-packages/rest_framework/views.py", line 509, in dispatch
    response = self.handle_exception(exc)
  File "/home/rashid/.cache/pypoetry/virtualenvs/cropgnosis-irOgLtvg-py3.10/lib/python3.10/site-packages/rest_framework/views.py", line 469, in handle_exception
    self.raise_uncaught_exception(exc)
  File "/home/rashid/.cache/pypoetry/virtualenvs/cropgnosis-irOgLtvg-py3.10/lib/python3.10/site-packages/rest_framework/views.py", line 480, in raise_uncaught_exception
    raise exc
  File "/home/rashid/.cache/pypoetry/virtualenvs/cropgnosis-irOgLtvg-py3.10/lib/python3.10/site-packages/rest_framework/views.py", line 506, in dispatch
    response = handler(request, *args, **kwargs)
  File "/home/rashid/Projects/CropGnosis/apps/authorization/views/mentor_view.py", line 87, in get
    return Response(serializer.user)
AttributeError: 'MentorAddressSerializer' object has no attribute 'user'
[16/Mar/2024 10:40:31] WARNING [django.request:241] Not Found: /api/auth/subscription/essential-features
[16/Mar/2024 10:40:52] WARNING [django.request:241] Not Found: /api/subscription/essential-features
[16/Mar/2024 10:44:35] WARNING [django.request:241] Unauthorized: /api/subscription/admin/essential-features
[16/Mar/2024 10:45:08] WARNING [django.request:241] Forbidden: /api/subscription/admin/essential-features
[16/Mar/2024 10:49:23] WARNING [django.request:241] Not Found: /
[16/Mar/2024 10:49:24] WARNING [django.request:241] Not Found: /favicon.ico
[16/Mar/2024 11:27:25] ERROR [django.request:241] Internal Server Error: /api/common/base-plans
Traceback (most recent call last):
  File "/home/rashid/.cache/pypoetry/virtualenvs/cropgnosis-irOgLtvg-py3.10/lib/python3.10/site-packages/django/core/handlers/exception.py", line 55, in inner
    response = get_response(request)
  File "/home/rashid/.cache/pypoetry/virtualenvs/cropgnosis-irOgLtvg-py3.10/lib/python3.10/site-packages/django/core/handlers/base.py", line 197, in _get_response
    response = wrapped_callback(request, *callback_args, **callback_kwargs)
  File "/home/rashid/.cache/pypoetry/virtualenvs/cropgnosis-irOgLtvg-py3.10/lib/python3.10/site-packages/django/views/decorators/csrf.py", line 65, in _view_wrapper
    return view_func(request, *args, **kwargs)
  File "/home/rashid/.cache/pypoetry/virtualenvs/cropgnosis-irOgLtvg-py3.10/lib/python3.10/site-packages/django/views/generic/base.py", line 104, in view
    return self.dispatch(request, *args, **kwargs)
  File "/home/rashid/.cache/pypoetry/virtualenvs/cropgnosis-irOgLtvg-py3.10/lib/python3.10/site-packages/rest_framework/views.py", line 509, in dispatch
    response = self.handle_exception(exc)
  File "/home/rashid/.cache/pypoetry/virtualenvs/cropgnosis-irOgLtvg-py3.10/lib/python3.10/site-packages/rest_framework/views.py", line 469, in handle_exception
    self.raise_uncaught_exception(exc)
  File "/home/rashid/.cache/pypoetry/virtualenvs/cropgnosis-irOgLtvg-py3.10/lib/python3.10/site-packages/rest_framework/views.py", line 480, in raise_uncaught_exception
    raise exc
  File "/home/rashid/.cache/pypoetry/virtualenvs/cropgnosis-irOgLtvg-py3.10/lib/python3.10/site-packages/rest_framework/views.py", line 506, in dispatch
    response = handler(request, *args, **kwargs)
  File "/home/rashid/.cache/pypoetry/virtualenvs/cropgnosis-irOgLtvg-py3.10/lib/python3.10/site-packages/rest_framework/generics.py", line 199, in get
    return self.list(request, *args, **kwargs)
  File "/home/rashid/.cache/pypoetry/virtualenvs/cropgnosis-irOgLtvg-py3.10/lib/python3.10/site-packages/rest_framework/mixins.py", line 46, in list
    return Response(serializer.data)
  File "/home/rashid/.cache/pypoetry/virtualenvs/cropgnosis-irOgLtvg-py3.10/lib/python3.10/site-packages/rest_framework/serializers.py", line 768, in data
    ret = super().data
  File "/home/rashid/.cache/pypoetry/virtualenvs/cropgnosis-irOgLtvg-py3.10/lib/python3.10/site-packages/rest_framework/serializers.py", line 253, in data
    self._data = self.to_representation(self.instance)
  File "/home/rashid/.cache/pypoetry/virtualenvs/cropgnosis-irOgLtvg-py3.10/lib/python3.10/site-packages/rest_framework/serializers.py", line 686, in to_representation
    return [
  File "/home/rashid/.cache/pypoetry/virtualenvs/cropgnosis-irOgLtvg-py3.10/lib/python3.10/site-packages/rest_framework/serializers.py", line 687, in <listcomp>
    self.child.to_representation(item) for item in iterable
  File "/home/rashid/.cache/pypoetry/virtualenvs/cropgnosis-irOgLtvg-py3.10/lib/python3.10/site-packages/rest_framework/serializers.py", line 507, in to_representation
    for field in fields:
  File "/home/rashid/.cache/pypoetry/virtualenvs/cropgnosis-irOgLtvg-py3.10/lib/python3.10/site-packages/rest_framework/serializers.py", line 368, in _readable_fields
    for field in self.fields.values():
  File "/home/rashid/.cache/pypoetry/virtualenvs/cropgnosis-irOgLtvg-py3.10/lib/python3.10/site-packages/django/utils/functional.py", line 47, in __get__
    res = instance.__dict__[self.name] = self.func(instance)
  File "/home/rashid/.cache/pypoetry/virtualenvs/cropgnosis-irOgLtvg-py3.10/lib/python3.10/site-packages/rest_framework/serializers.py", line 356, in fields
    for key, value in self.get_fields().items():
  File "/home/rashid/.cache/pypoetry/virtualenvs/cropgnosis-irOgLtvg-py3.10/lib/python3.10/site-packages/rest_framework/serializers.py", line 1076, in get_fields
    field_class, field_kwargs = self.build_field(
  File "/home/rashid/.cache/pypoetry/virtualenvs/cropgnosis-irOgLtvg-py3.10/lib/python3.10/site-packages/rest_framework/serializers.py", line 1222, in build_field
    return self.build_unknown_field(field_name, model_class)
  File "/home/rashid/.cache/pypoetry/virtualenvs/cropgnosis-irOgLtvg-py3.10/lib/python3.10/site-packages/rest_framework/serializers.py", line 1340, in build_unknown_field
    raise ImproperlyConfigured(
django.core.exceptions.ImproperlyConfigured: Field name `features_lt` is not valid for model `BaseSubscriptionPlans`.
[16/Mar/2024 11:27:55] ERROR [django.request:241] Internal Server Error: /api/common/base-plans
Traceback (most recent call last):
  File "/home/rashid/.cache/pypoetry/virtualenvs/cropgnosis-irOgLtvg-py3.10/lib/python3.10/site-packages/rest_framework/fields.py", line 446, in get_attribute
    return get_attribute(instance, self.source_attrs)
  File "/home/rashid/.cache/pypoetry/virtualenvs/cropgnosis-irOgLtvg-py3.10/lib/python3.10/site-packages/rest_framework/fields.py", line 96, in get_attribute
    instance = getattr(instance, attr)
AttributeError: 'BaseSubscriptionPlans' object has no attribute 'features_lt'

During handling of the above exception, another exception occurred:

Traceback (most recent call last):
  File "/home/rashid/.cache/pypoetry/virtualenvs/cropgnosis-irOgLtvg-py3.10/lib/python3.10/site-packages/django/core/handlers/exception.py", line 55, in inner
    response = get_response(request)
  File "/home/rashid/.cache/pypoetry/virtualenvs/cropgnosis-irOgLtvg-py3.10/lib/python3.10/site-packages/django/core/handlers/base.py", line 197, in _get_response
    response = wrapped_callback(request, *callback_args, **callback_kwargs)
  File "/home/rashid/.cache/pypoetry/virtualenvs/cropgnosis-irOgLtvg-py3.10/lib/python3.10/site-packages/django/views/decorators/csrf.py", line 65, in _view_wrapper
    return view_func(request, *args, **kwargs)
  File "/home/rashid/.cache/pypoetry/virtualenvs/cropgnosis-irOgLtvg-py3.10/lib/python3.10/site-packages/django/views/generic/base.py", line 104, in view
    return self.dispatch(request, *args, **kwargs)
  File "/home/rashid/.cache/pypoetry/virtualenvs/cropgnosis-irOgLtvg-py3.10/lib/python3.10/site-packages/rest_framework/views.py", line 509, in dispatch
    response = self.handle_exception(exc)
  File "/home/rashid/.cache/pypoetry/virtualenvs/cropgnosis-irOgLtvg-py3.10/lib/python3.10/site-packages/rest_framework/views.py", line 469, in handle_exception
    self.raise_uncaught_exception(exc)
  File "/home/rashid/.cache/pypoetry/virtualenvs/cropgnosis-irOgLtvg-py3.10/lib/python3.10/site-packages/rest_framework/views.py", line 480, in raise_uncaught_exception
    raise exc
  File "/home/rashid/.cache/pypoetry/virtualenvs/cropgnosis-irOgLtvg-py3.10/lib/python3.10/site-packages/rest_framework/views.py", line 506, in dispatch
    response = handler(request, *args, **kwargs)
  File "/home/rashid/.cache/pypoetry/virtualenvs/cropgnosis-irOgLtvg-py3.10/lib/python3.10/site-packages/rest_framework/generics.py", line 199, in get
    return self.list(request, *args, **kwargs)
  File "/home/rashid/.cache/pypoetry/virtualenvs/cropgnosis-irOgLtvg-py3.10/lib/python3.10/site-packages/rest_framework/mixins.py", line 46, in list
    return Response(serializer.data)
  File "/home/rashid/.cache/pypoetry/virtualenvs/cropgnosis-irOgLtvg-py3.10/lib/python3.10/site-packages/rest_framework/serializers.py", line 768, in data
    ret = super().data
  File "/home/rashid/.cache/pypoetry/virtualenvs/cropgnosis-irOgLtvg-py3.10/lib/python3.10/site-packages/rest_framework/serializers.py", line 253, in data
    self._data = self.to_representation(self.instance)
  File "/home/rashid/.cache/pypoetry/virtualenvs/cropgnosis-irOgLtvg-py3.10/lib/python3.10/site-packages/rest_framework/serializers.py", line 686, in to_representation
    return [
  File "/home/rashid/.cache/pypoetry/virtualenvs/cropgnosis-irOgLtvg-py3.10/lib/python3.10/site-packages/rest_framework/serializers.py", line 687, in <listcomp>
    self.child.to_representation(item) for item in iterable
  File "/home/rashid/.cache/pypoetry/virtualenvs/cropgnosis-irOgLtvg-py3.10/lib/python3.10/site-packages/rest_framework/serializers.py", line 509, in to_representation
    attribute = field.get_attribute(instance)
  File "/home/rashid/.cache/pypoetry/virtualenvs/cropgnosis-irOgLtvg-py3.10/lib/python3.10/site-packages/rest_framework/fields.py", line 479, in get_attribute
    raise type(exc)(msg)
AttributeError: Got AttributeError when attempting to get a value for field `features_lt` on serializer `BasePlanSerializer`.
The serializer field might be named incorrectly and not match any attribute or key on the `BaseSubscriptionPlans` instance.
Original exception text was: 'BaseSubscriptionPlans' object has no attribute 'features_lt'.
[16/Mar/2024 11:28:10] ERROR [django.request:241] Internal Server Error: /api/common/base-plans
Traceback (most recent call last):
  File "/home/rashid/.cache/pypoetry/virtualenvs/cropgnosis-irOgLtvg-py3.10/lib/python3.10/site-packages/rest_framework/fields.py", line 446, in get_attribute
    return get_attribute(instance, self.source_attrs)
  File "/home/rashid/.cache/pypoetry/virtualenvs/cropgnosis-irOgLtvg-py3.10/lib/python3.10/site-packages/rest_framework/fields.py", line 96, in get_attribute
    instance = getattr(instance, attr)
AttributeError: 'ManyRelatedManager' object has no attribute 'feature'

During handling of the above exception, another exception occurred:

Traceback (most recent call last):
  File "/home/rashid/.cache/pypoetry/virtualenvs/cropgnosis-irOgLtvg-py3.10/lib/python3.10/site-packages/django/core/handlers/exception.py", line 55, in inner
    response = get_response(request)
  File "/home/rashid/.cache/pypoetry/virtualenvs/cropgnosis-irOgLtvg-py3.10/lib/python3.10/site-packages/django/core/handlers/base.py", line 197, in _get_response
    response = wrapped_callback(request, *callback_args, **callback_kwargs)
  File "/home/rashid/.cache/pypoetry/virtualenvs/cropgnosis-irOgLtvg-py3.10/lib/python3.10/site-packages/django/views/decorators/csrf.py", line 65, in _view_wrapper
    return view_func(request, *args, **kwargs)
  File "/home/rashid/.cache/pypoetry/virtualenvs/cropgnosis-irOgLtvg-py3.10/lib/python3.10/site-packages/django/views/generic/base.py", line 104, in view
    return self.dispatch(request, *args, **kwargs)
  File "/home/rashid/.cache/pypoetry/virtualenvs/cropgnosis-irOgLtvg-py3.10/lib/python3.10/site-packages/rest_framework/views.py", line 509, in dispatch
    response = self.handle_exception(exc)
  File "/home/rashid/.cache/pypoetry/virtualenvs/cropgnosis-irOgLtvg-py3.10/lib/python3.10/site-packages/rest_framework/views.py", line 469, in handle_exception
    self.raise_uncaught_exception(exc)
  File "/home/rashid/.cache/pypoetry/virtualenvs/cropgnosis-irOgLtvg-py3.10/lib/python3.10/site-packages/rest_framework/views.py", line 480, in raise_uncaught_exception
    raise exc
  File "/home/rashid/.cache/pypoetry/virtualenvs/cropgnosis-irOgLtvg-py3.10/lib/python3.10/site-packages/rest_framework/views.py", line 506, in dispatch
    response = handler(request, *args, **kwargs)
  File "/home/rashid/.cache/pypoetry/virtualenvs/cropgnosis-irOgLtvg-py3.10/lib/python3.10/site-packages/rest_framework/generics.py", line 199, in get
    return self.list(request, *args, **kwargs)
  File "/home/rashid/.cache/pypoetry/virtualenvs/cropgnosis-irOgLtvg-py3.10/lib/python3.10/site-packages/rest_framework/mixins.py", line 46, in list
    return Response(serializer.data)
  File "/home/rashid/.cache/pypoetry/virtualenvs/cropgnosis-irOgLtvg-py3.10/lib/python3.10/site-packages/rest_framework/serializers.py", line 768, in data
    ret = super().data
  File "/home/rashid/.cache/pypoetry/virtualenvs/cropgnosis-irOgLtvg-py3.10/lib/python3.10/site-packages/rest_framework/serializers.py", line 253, in data
    self._data = self.to_representation(self.instance)
  File "/home/rashid/.cache/pypoetry/virtualenvs/cropgnosis-irOgLtvg-py3.10/lib/python3.10/site-packages/rest_framework/serializers.py", line 686, in to_representation
    return [
  File "/home/rashid/.cache/pypoetry/virtualenvs/cropgnosis-irOgLtvg-py3.10/lib/python3.10/site-packages/rest_framework/serializers.py", line 687, in <listcomp>
    self.child.to_representation(item) for item in iterable
  File "/home/rashid/.cache/pypoetry/virtualenvs/cropgnosis-irOgLtvg-py3.10/lib/python3.10/site-packages/rest_framework/serializers.py", line 522, in to_representation
    ret[field.field_name] = field.to_representation(attribute)
  File "/home/rashid/.cache/pypoetry/virtualenvs/cropgnosis-irOgLtvg-py3.10/lib/python3.10/site-packages/rest_framework/serializers.py", line 509, in to_representation
    attribute = field.get_attribute(instance)
  File "/home/rashid/.cache/pypoetry/virtualenvs/cropgnosis-irOgLtvg-py3.10/lib/python3.10/site-packages/rest_framework/fields.py", line 479, in get_attribute
    raise type(exc)(msg)
AttributeError: Got AttributeError when attempting to get a value for field `feature` on serializer `EssentialFeaturSerializer`.
The serializer field might be named incorrectly and not match any attribute or key on the `ManyRelatedManager` instance.
Original exception text was: 'ManyRelatedManager' object has no attribute 'feature'.
[16/Mar/2024 11:28:35] ERROR [django.request:241] Internal Server Error: /api/common/base-plans
Traceback (most recent call last):
  File "/home/rashid/.cache/pypoetry/virtualenvs/cropgnosis-irOgLtvg-py3.10/lib/python3.10/site-packages/rest_framework/fields.py", line 446, in get_attribute
    return get_attribute(instance, self.source_attrs)
  File "/home/rashid/.cache/pypoetry/virtualenvs/cropgnosis-irOgLtvg-py3.10/lib/python3.10/site-packages/rest_framework/fields.py", line 96, in get_attribute
    instance = getattr(instance, attr)
AttributeError: 'ManyRelatedManager' object has no attribute 'feature'

During handling of the above exception, another exception occurred:

Traceback (most recent call last):
  File "/home/rashid/.cache/pypoetry/virtualenvs/cropgnosis-irOgLtvg-py3.10/lib/python3.10/site-packages/django/core/handlers/exception.py", line 55, in inner
    response = get_response(request)
  File "/home/rashid/.cache/pypoetry/virtualenvs/cropgnosis-irOgLtvg-py3.10/lib/python3.10/site-packages/django/core/handlers/base.py", line 197, in _get_response
    response = wrapped_callback(request, *callback_args, **callback_kwargs)
  File "/home/rashid/.cache/pypoetry/virtualenvs/cropgnosis-irOgLtvg-py3.10/lib/python3.10/site-packages/django/views/decorators/csrf.py", line 65, in _view_wrapper
    return view_func(request, *args, **kwargs)
  File "/home/rashid/.cache/pypoetry/virtualenvs/cropgnosis-irOgLtvg-py3.10/lib/python3.10/site-packages/django/views/generic/base.py", line 104, in view
    return self.dispatch(request, *args, **kwargs)
  File "/home/rashid/.cache/pypoetry/virtualenvs/cropgnosis-irOgLtvg-py3.10/lib/python3.10/site-packages/rest_framework/views.py", line 509, in dispatch
    response = self.handle_exception(exc)
  File "/home/rashid/.cache/pypoetry/virtualenvs/cropgnosis-irOgLtvg-py3.10/lib/python3.10/site-packages/rest_framework/views.py", line 469, in handle_exception
    self.raise_uncaught_exception(exc)
  File "/home/rashid/.cache/pypoetry/virtualenvs/cropgnosis-irOgLtvg-py3.10/lib/python3.10/site-packages/rest_framework/views.py", line 480, in raise_uncaught_exception
    raise exc
  File "/home/rashid/.cache/pypoetry/virtualenvs/cropgnosis-irOgLtvg-py3.10/lib/python3.10/site-packages/rest_framework/views.py", line 506, in dispatch
    response = handler(request, *args, **kwargs)
  File "/home/rashid/.cache/pypoetry/virtualenvs/cropgnosis-irOgLtvg-py3.10/lib/python3.10/site-packages/rest_framework/generics.py", line 199, in get
    return self.list(request, *args, **kwargs)
  File "/home/rashid/.cache/pypoetry/virtualenvs/cropgnosis-irOgLtvg-py3.10/lib/python3.10/site-packages/rest_framework/mixins.py", line 46, in list
    return Response(serializer.data)
  File "/home/rashid/.cache/pypoetry/virtualenvs/cropgnosis-irOgLtvg-py3.10/lib/python3.10/site-packages/rest_framework/serializers.py", line 768, in data
    ret = super().data
  File "/home/rashid/.cache/pypoetry/virtualenvs/cropgnosis-irOgLtvg-py3.10/lib/python3.10/site-packages/rest_framework/serializers.py", line 253, in data
    self._data = self.to_representation(self.instance)
  File "/home/rashid/.cache/pypoetry/virtualenvs/cropgnosis-irOgLtvg-py3.10/lib/python3.10/site-packages/rest_framework/serializers.py", line 686, in to_representation
    return [
  File "/home/rashid/.cache/pypoetry/virtualenvs/cropgnosis-irOgLtvg-py3.10/lib/python3.10/site-packages/rest_framework/serializers.py", line 687, in <listcomp>
    self.child.to_representation(item) for item in iterable
  File "/home/rashid/.cache/pypoetry/virtualenvs/cropgnosis-irOgLtvg-py3.10/lib/python3.10/site-packages/rest_framework/serializers.py", line 522, in to_representation
    ret[field.field_name] = field.to_representation(attribute)
  File "/home/rashid/.cache/pypoetry/virtualenvs/cropgnosis-irOgLtvg-py3.10/lib/python3.10/site-packages/rest_framework/serializers.py", line 509, in to_representation
    attribute = field.get_attribute(instance)
  File "/home/rashid/.cache/pypoetry/virtualenvs/cropgnosis-irOgLtvg-py3.10/lib/python3.10/site-packages/rest_framework/fields.py", line 479, in get_attribute
    raise type(exc)(msg)
AttributeError: Got AttributeError when attempting to get a value for field `feature` on serializer `EssentialFeaturSerializer`.
The serializer field might be named incorrectly and not match any attribute or key on the `ManyRelatedManager` instance.
Original exception text was: 'ManyRelatedManager' object has no attribute 'feature'.
[16/Mar/2024 11:29:23] ERROR [django.request:241] Internal Server Error: /api/common/base-plans
Traceback (most recent call last):
  File "/home/rashid/.cache/pypoetry/virtualenvs/cropgnosis-irOgLtvg-py3.10/lib/python3.10/site-packages/rest_framework/fields.py", line 446, in get_attribute
    return get_attribute(instance, self.source_attrs)
  File "/home/rashid/.cache/pypoetry/virtualenvs/cropgnosis-irOgLtvg-py3.10/lib/python3.10/site-packages/rest_framework/fields.py", line 96, in get_attribute
    instance = getattr(instance, attr)
AttributeError: 'ManyRelatedManager' object has no attribute 'feature'

During handling of the above exception, another exception occurred:

Traceback (most recent call last):
  File "/home/rashid/.cache/pypoetry/virtualenvs/cropgnosis-irOgLtvg-py3.10/lib/python3.10/site-packages/django/core/handlers/exception.py", line 55, in inner
    response = get_response(request)
  File "/home/rashid/.cache/pypoetry/virtualenvs/cropgnosis-irOgLtvg-py3.10/lib/python3.10/site-packages/django/core/handlers/base.py", line 197, in _get_response
    response = wrapped_callback(request, *callback_args, **callback_kwargs)
  File "/home/rashid/.cache/pypoetry/virtualenvs/cropgnosis-irOgLtvg-py3.10/lib/python3.10/site-packages/django/views/decorators/csrf.py", line 65, in _view_wrapper
    return view_func(request, *args, **kwargs)
  File "/home/rashid/.cache/pypoetry/virtualenvs/cropgnosis-irOgLtvg-py3.10/lib/python3.10/site-packages/django/views/generic/base.py", line 104, in view
    return self.dispatch(request, *args, **kwargs)
  File "/home/rashid/.cache/pypoetry/virtualenvs/cropgnosis-irOgLtvg-py3.10/lib/python3.10/site-packages/rest_framework/views.py", line 509, in dispatch
    response = self.handle_exception(exc)
  File "/home/rashid/.cache/pypoetry/virtualenvs/cropgnosis-irOgLtvg-py3.10/lib/python3.10/site-packages/rest_framework/views.py", line 469, in handle_exception
    self.raise_uncaught_exception(exc)
  File "/home/rashid/.cache/pypoetry/virtualenvs/cropgnosis-irOgLtvg-py3.10/lib/python3.10/site-packages/rest_framework/views.py", line 480, in raise_uncaught_exception
    raise exc
  File "/home/rashid/.cache/pypoetry/virtualenvs/cropgnosis-irOgLtvg-py3.10/lib/python3.10/site-packages/rest_framework/views.py", line 506, in dispatch
    response = handler(request, *args, **kwargs)
  File "/home/rashid/.cache/pypoetry/virtualenvs/cropgnosis-irOgLtvg-py3.10/lib/python3.10/site-packages/rest_framework/generics.py", line 199, in get
    return self.list(request, *args, **kwargs)
  File "/home/rashid/.cache/pypoetry/virtualenvs/cropgnosis-irOgLtvg-py3.10/lib/python3.10/site-packages/rest_framework/mixins.py", line 46, in list
    return Response(serializer.data)
  File "/home/rashid/.cache/pypoetry/virtualenvs/cropgnosis-irOgLtvg-py3.10/lib/python3.10/site-packages/rest_framework/serializers.py", line 768, in data
    ret = super().data
  File "/home/rashid/.cache/pypoetry/virtualenvs/cropgnosis-irOgLtvg-py3.10/lib/python3.10/site-packages/rest_framework/serializers.py", line 253, in data
    self._data = self.to_representation(self.instance)
  File "/home/rashid/.cache/pypoetry/virtualenvs/cropgnosis-irOgLtvg-py3.10/lib/python3.10/site-packages/rest_framework/serializers.py", line 686, in to_representation
    return [
  File "/home/rashid/.cache/pypoetry/virtualenvs/cropgnosis-irOgLtvg-py3.10/lib/python3.10/site-packages/rest_framework/serializers.py", line 687, in <listcomp>
    self.child.to_representation(item) for item in iterable
  File "/home/rashid/.cache/pypoetry/virtualenvs/cropgnosis-irOgLtvg-py3.10/lib/python3.10/site-packages/rest_framework/serializers.py", line 522, in to_representation
    ret[field.field_name] = field.to_representation(attribute)
  File "/home/rashid/.cache/pypoetry/virtualenvs/cropgnosis-irOgLtvg-py3.10/lib/python3.10/site-packages/rest_framework/serializers.py", line 509, in to_representation
    attribute = field.get_attribute(instance)
  File "/home/rashid/.cache/pypoetry/virtualenvs/cropgnosis-irOgLtvg-py3.10/lib/python3.10/site-packages/rest_framework/fields.py", line 479, in get_attribute
    raise type(exc)(msg)
AttributeError: Got AttributeError when attempting to get a value for field `feature` on serializer `EssentialFeaturSerializer`.
The serializer field might be named incorrectly and not match any attribute or key on the `ManyRelatedManager` instance.
Original exception text was: 'ManyRelatedManager' object has no attribute 'feature'.
[16/Mar/2024 11:31:22] ERROR [django.request:241] Internal Server Error: /api/common/base-plans
Traceback (most recent call last):
  File "/home/rashid/.cache/pypoetry/virtualenvs/cropgnosis-irOgLtvg-py3.10/lib/python3.10/site-packages/django/core/handlers/exception.py", line 55, in inner
    response = get_response(request)
  File "/home/rashid/.cache/pypoetry/virtualenvs/cropgnosis-irOgLtvg-py3.10/lib/python3.10/site-packages/django/core/handlers/base.py", line 197, in _get_response
    response = wrapped_callback(request, *callback_args, **callback_kwargs)
  File "/home/rashid/.cache/pypoetry/virtualenvs/cropgnosis-irOgLtvg-py3.10/lib/python3.10/site-packages/django/views/decorators/csrf.py", line 65, in _view_wrapper
    return view_func(request, *args, **kwargs)
  File "/home/rashid/.cache/pypoetry/virtualenvs/cropgnosis-irOgLtvg-py3.10/lib/python3.10/site-packages/django/views/generic/base.py", line 104, in view
    return self.dispatch(request, *args, **kwargs)
  File "/home/rashid/.cache/pypoetry/virtualenvs/cropgnosis-irOgLtvg-py3.10/lib/python3.10/site-packages/rest_framework/views.py", line 509, in dispatch
    response = self.handle_exception(exc)
  File "/home/rashid/.cache/pypoetry/virtualenvs/cropgnosis-irOgLtvg-py3.10/lib/python3.10/site-packages/rest_framework/views.py", line 469, in handle_exception
    self.raise_uncaught_exception(exc)
  File "/home/rashid/.cache/pypoetry/virtualenvs/cropgnosis-irOgLtvg-py3.10/lib/python3.10/site-packages/rest_framework/views.py", line 480, in raise_uncaught_exception
    raise exc
  File "/home/rashid/.cache/pypoetry/virtualenvs/cropgnosis-irOgLtvg-py3.10/lib/python3.10/site-packages/rest_framework/views.py", line 506, in dispatch
    response = handler(request, *args, **kwargs)
  File "/home/rashid/.cache/pypoetry/virtualenvs/cropgnosis-irOgLtvg-py3.10/lib/python3.10/site-packages/rest_framework/generics.py", line 199, in get
    return self.list(request, *args, **kwargs)
  File "/home/rashid/.cache/pypoetry/virtualenvs/cropgnosis-irOgLtvg-py3.10/lib/python3.10/site-packages/rest_framework/mixins.py", line 46, in list
    return Response(serializer.data)
  File "/home/rashid/.cache/pypoetry/virtualenvs/cropgnosis-irOgLtvg-py3.10/lib/python3.10/site-packages/rest_framework/serializers.py", line 768, in data
    ret = super().data
  File "/home/rashid/.cache/pypoetry/virtualenvs/cropgnosis-irOgLtvg-py3.10/lib/python3.10/site-packages/rest_framework/serializers.py", line 253, in data
    self._data = self.to_representation(self.instance)
  File "/home/rashid/.cache/pypoetry/virtualenvs/cropgnosis-irOgLtvg-py3.10/lib/python3.10/site-packages/rest_framework/serializers.py", line 686, in to_representation
    return [
  File "/home/rashid/.cache/pypoetry/virtualenvs/cropgnosis-irOgLtvg-py3.10/lib/python3.10/site-packages/rest_framework/serializers.py", line 687, in <listcomp>
    self.child.to_representation(item) for item in iterable
  File "/home/rashid/.cache/pypoetry/virtualenvs/cropgnosis-irOgLtvg-py3.10/lib/python3.10/site-packages/rest_framework/serializers.py", line 522, in to_representation
    ret[field.field_name] = field.to_representation(attribute)
  File "/home/rashid/.cache/pypoetry/virtualenvs/cropgnosis-irOgLtvg-py3.10/lib/python3.10/site-packages/rest_framework/serializers.py", line 686, in to_representation
    return [
  File "/home/rashid/.cache/pypoetry/virtualenvs/cropgnosis-irOgLtvg-py3.10/lib/python3.10/site-packages/rest_framework/serializers.py", line 687, in <listcomp>
    self.child.to_representation(item) for item in iterable
  File "/home/rashid/.cache/pypoetry/virtualenvs/cropgnosis-irOgLtvg-py3.10/lib/python3.10/site-packages/rest_framework/serializers.py", line 507, in to_representation
    for field in fields:
  File "/home/rashid/.cache/pypoetry/virtualenvs/cropgnosis-irOgLtvg-py3.10/lib/python3.10/site-packages/rest_framework/serializers.py", line 368, in _readable_fields
    for field in self.fields.values():
  File "/home/rashid/.cache/pypoetry/virtualenvs/cropgnosis-irOgLtvg-py3.10/lib/python3.10/site-packages/django/utils/functional.py", line 47, in __get__
    res = instance.__dict__[self.name] = self.func(instance)
  File "/home/rashid/.cache/pypoetry/virtualenvs/cropgnosis-irOgLtvg-py3.10/lib/python3.10/site-packages/rest_framework/serializers.py", line 356, in fields
    for key, value in self.get_fields().items():
  File "/home/rashid/.cache/pypoetry/virtualenvs/cropgnosis-irOgLtvg-py3.10/lib/python3.10/site-packages/rest_framework/serializers.py", line 1052, in get_fields
    field_names = self.get_field_names(declared_fields, info)
  File "/home/rashid/.cache/pypoetry/virtualenvs/cropgnosis-irOgLtvg-py3.10/lib/python3.10/site-packages/rest_framework/serializers.py", line 1117, in get_field_names
    assert not (fields and exclude), (
AssertionError: Cannot set both 'fields' and 'exclude' options on serializer EssentialFeaturSerializer.
[18/Mar/2024 05:14:08] WARNING [django.request:241] Not Found: /
[18/Mar/2024 05:14:27] WARNING [django.request:241] Not Found: /api/subscription/
[18/Mar/2024 05:14:35] WARNING [django.request:241] Method Not Allowed: /api/subscription/check-out
[20/Mar/2024 03:41:37] WARNING [django.request:241] Not Found: /
[20/Mar/2024 03:41:38] WARNING [django.request:241] Not Found: /favicon.ico
[20/Mar/2024 03:41:49] WARNING [django.request:241] Not Found: /
[20/Mar/2024 03:42:39] WARNING [django.request:241] Not Found: /
[20/Mar/2024 03:42:45] WARNING [django.request:241] Not Found: /api/auth/login/
[20/Mar/2024 03:43:00] WARNING [django.request:241] Method Not Allowed: /api/auth/customer/login
[26/Mar/2024 15:44:42] WARNING [django.request:241] Not Found: /api/check-out/
[26/Mar/2024 15:45:09] WARNING [django.request:241] Not Found: /api/subscription/check-out/
[26/Mar/2024 15:45:18] WARNING [django.request:241] Not Found: /api/subscriptions/check-out/
[26/Mar/2024 15:46:38] ERROR [django.request:241] Internal Server Error: /api/subscription/check-out
Traceback (most recent call last):
  File "/home/rashid/.cache/pypoetry/virtualenvs/cropgnosis-irOgLtvg-py3.10/lib/python3.10/site-packages/django/core/handlers/exception.py", line 55, in inner
    response = get_response(request)
  File "/home/rashid/.cache/pypoetry/virtualenvs/cropgnosis-irOgLtvg-py3.10/lib/python3.10/site-packages/django/core/handlers/base.py", line 197, in _get_response
    response = wrapped_callback(request, *callback_args, **callback_kwargs)
  File "/home/rashid/.cache/pypoetry/virtualenvs/cropgnosis-irOgLtvg-py3.10/lib/python3.10/site-packages/django/views/decorators/csrf.py", line 65, in _view_wrapper
    return view_func(request, *args, **kwargs)
  File "/home/rashid/.cache/pypoetry/virtualenvs/cropgnosis-irOgLtvg-py3.10/lib/python3.10/site-packages/django/views/generic/base.py", line 104, in view
    return self.dispatch(request, *args, **kwargs)
  File "/home/rashid/.cache/pypoetry/virtualenvs/cropgnosis-irOgLtvg-py3.10/lib/python3.10/site-packages/rest_framework/views.py", line 509, in dispatch
    response = self.handle_exception(exc)
  File "/home/rashid/.cache/pypoetry/virtualenvs/cropgnosis-irOgLtvg-py3.10/lib/python3.10/site-packages/rest_framework/views.py", line 469, in handle_exception
    self.raise_uncaught_exception(exc)
  File "/home/rashid/.cache/pypoetry/virtualenvs/cropgnosis-irOgLtvg-py3.10/lib/python3.10/site-packages/rest_framework/views.py", line 480, in raise_uncaught_exception
    raise exc
  File "/home/rashid/.cache/pypoetry/virtualenvs/cropgnosis-irOgLtvg-py3.10/lib/python3.10/site-packages/rest_framework/views.py", line 506, in dispatch
    response = handler(request, *args, **kwargs)
  File "/home/rashid/Projects/CropGnosis/apps/subscription/views/customer_views.py", line 25, in get
    return render("checkout.html")
TypeError: render() missing 1 required positional argument: 'template_name'
[26/Mar/2024 15:47:20] WARNING [django.request:241] Not Found: /api/subscription/style.css
[26/Mar/2024 15:47:22] WARNING [django.request:241] Not Found: /create-checkout-session
[26/Mar/2024 15:47:46] WARNING [django.request:241] Not Found: /api/subscription/style.css
[26/Mar/2024 15:47:47] WARNING [django.request:241] Not Found: /favicon.ico
[26/Mar/2024 16:04:42] WARNING [django.request:241] Not Found: /api/subscription/style.css
[26/Mar/2024 17:25:43] WARNING [django.request:241] Not Found: /
[26/Mar/2024 17:34:03] ERROR [django.request:241] Internal Server Error: /api/subscription/check-out
Traceback (most recent call last):
  File "/home/rashid/.cache/pypoetry/virtualenvs/cropgnosis-irOgLtvg-py3.10/lib/python3.10/site-packages/django/core/handlers/exception.py", line 55, in inner
    response = get_response(request)
  File "/home/rashid/.cache/pypoetry/virtualenvs/cropgnosis-irOgLtvg-py3.10/lib/python3.10/site-packages/django/core/handlers/base.py", line 197, in _get_response
    response = wrapped_callback(request, *callback_args, **callback_kwargs)
  File "/home/rashid/.cache/pypoetry/virtualenvs/cropgnosis-irOgLtvg-py3.10/lib/python3.10/site-packages/django/views/decorators/csrf.py", line 65, in _view_wrapper
    return view_func(request, *args, **kwargs)
  File "/home/rashid/.cache/pypoetry/virtualenvs/cropgnosis-irOgLtvg-py3.10/lib/python3.10/site-packages/django/views/generic/base.py", line 104, in view
    return self.dispatch(request, *args, **kwargs)
  File "/home/rashid/.cache/pypoetry/virtualenvs/cropgnosis-irOgLtvg-py3.10/lib/python3.10/site-packages/rest_framework/views.py", line 509, in dispatch
    response = self.handle_exception(exc)
  File "/home/rashid/.cache/pypoetry/virtualenvs/cropgnosis-irOgLtvg-py3.10/lib/python3.10/site-packages/rest_framework/views.py", line 469, in handle_exception
    self.raise_uncaught_exception(exc)
  File "/home/rashid/.cache/pypoetry/virtualenvs/cropgnosis-irOgLtvg-py3.10/lib/python3.10/site-packages/rest_framework/views.py", line 480, in raise_uncaught_exception
    raise exc
  File "/home/rashid/.cache/pypoetry/virtualenvs/cropgnosis-irOgLtvg-py3.10/lib/python3.10/site-packages/rest_framework/views.py", line 506, in dispatch
    response = handler(request, *args, **kwargs)
  File "/home/rashid/Projects/CropGnosis/apps/subscription/views/customer_views.py", line 27, in post
    stripe_customer_id = user_address.remark.get("stripe_customer_id")
AttributeError: 'NoneType' object has no attribute 'get'
[27/Mar/2024 06:47:56] ERROR [django.request:241] Internal Server Error: /api/subscription/subscription-check-out
Traceback (most recent call last):
  File "/home/rashid/.cache/pypoetry/virtualenvs/cropgnosis-irOgLtvg-py3.10/lib/python3.10/site-packages/django/core/handlers/exception.py", line 55, in inner
    response = get_response(request)
  File "/home/rashid/.cache/pypoetry/virtualenvs/cropgnosis-irOgLtvg-py3.10/lib/python3.10/site-packages/django/core/handlers/base.py", line 197, in _get_response
    response = wrapped_callback(request, *callback_args, **callback_kwargs)
  File "/home/rashid/.cache/pypoetry/virtualenvs/cropgnosis-irOgLtvg-py3.10/lib/python3.10/site-packages/django/views/decorators/csrf.py", line 65, in _view_wrapper
    return view_func(request, *args, **kwargs)
  File "/home/rashid/.cache/pypoetry/virtualenvs/cropgnosis-irOgLtvg-py3.10/lib/python3.10/site-packages/django/views/generic/base.py", line 104, in view
    return self.dispatch(request, *args, **kwargs)
  File "/home/rashid/.cache/pypoetry/virtualenvs/cropgnosis-irOgLtvg-py3.10/lib/python3.10/site-packages/rest_framework/views.py", line 509, in dispatch
    response = self.handle_exception(exc)
  File "/home/rashid/.cache/pypoetry/virtualenvs/cropgnosis-irOgLtvg-py3.10/lib/python3.10/site-packages/rest_framework/views.py", line 469, in handle_exception
    self.raise_uncaught_exception(exc)
  File "/home/rashid/.cache/pypoetry/virtualenvs/cropgnosis-irOgLtvg-py3.10/lib/python3.10/site-packages/rest_framework/views.py", line 480, in raise_uncaught_exception
    raise exc
  File "/home/rashid/.cache/pypoetry/virtualenvs/cropgnosis-irOgLtvg-py3.10/lib/python3.10/site-packages/rest_framework/views.py", line 506, in dispatch
    response = handler(request, *args, **kwargs)
  File "/home/rashid/Projects/CropGnosis/apps/subscription/views/customer_views.py", line 24, in post
    self.error_response("subscription_plan is required")
AttributeError: 'SubscriptionCheckOut' object has no attribute 'error_response'
[27/Mar/2024 06:48:47] ERROR [django.request:241] Internal Server Error: /api/subscription/subscription-check-out
Traceback (most recent call last):
  File "/home/rashid/.cache/pypoetry/virtualenvs/cropgnosis-irOgLtvg-py3.10/lib/python3.10/site-packages/django/core/handlers/exception.py", line 55, in inner
    response = get_response(request)
  File "/home/rashid/.cache/pypoetry/virtualenvs/cropgnosis-irOgLtvg-py3.10/lib/python3.10/site-packages/django/core/handlers/base.py", line 197, in _get_response
    response = wrapped_callback(request, *callback_args, **callback_kwargs)
  File "/home/rashid/.cache/pypoetry/virtualenvs/cropgnosis-irOgLtvg-py3.10/lib/python3.10/site-packages/django/views/decorators/csrf.py", line 65, in _view_wrapper
    return view_func(request, *args, **kwargs)
  File "/home/rashid/.cache/pypoetry/virtualenvs/cropgnosis-irOgLtvg-py3.10/lib/python3.10/site-packages/django/views/generic/base.py", line 104, in view
    return self.dispatch(request, *args, **kwargs)
  File "/home/rashid/.cache/pypoetry/virtualenvs/cropgnosis-irOgLtvg-py3.10/lib/python3.10/site-packages/rest_framework/views.py", line 509, in dispatch
    response = self.handle_exception(exc)
  File "/home/rashid/.cache/pypoetry/virtualenvs/cropgnosis-irOgLtvg-py3.10/lib/python3.10/site-packages/rest_framework/views.py", line 469, in handle_exception
    self.raise_uncaught_exception(exc)
  File "/home/rashid/.cache/pypoetry/virtualenvs/cropgnosis-irOgLtvg-py3.10/lib/python3.10/site-packages/rest_framework/views.py", line 480, in raise_uncaught_exception
    raise exc
  File "/home/rashid/.cache/pypoetry/virtualenvs/cropgnosis-irOgLtvg-py3.10/lib/python3.10/site-packages/rest_framework/views.py", line 506, in dispatch
    response = handler(request, *args, **kwargs)
  File "/home/rashid/Projects/CropGnosis/apps/subscription/views/customer_views.py", line 24, in post
    self.error_messages("subscription_plan is required")
AttributeError: 'SubscriptionCheckOut' object has no attribute 'error_messages'
[27/Mar/2024 06:49:02] ERROR [django.request:241] Internal Server Error: /api/subscription/subscription-check-out
Traceback (most recent call last):
  File "/home/rashid/.cache/pypoetry/virtualenvs/cropgnosis-irOgLtvg-py3.10/lib/python3.10/site-packages/django/core/handlers/exception.py", line 55, in inner
    response = get_response(request)
  File "/home/rashid/.cache/pypoetry/virtualenvs/cropgnosis-irOgLtvg-py3.10/lib/python3.10/site-packages/django/core/handlers/base.py", line 197, in _get_response
    response = wrapped_callback(request, *callback_args, **callback_kwargs)
  File "/home/rashid/.cache/pypoetry/virtualenvs/cropgnosis-irOgLtvg-py3.10/lib/python3.10/site-packages/django/views/decorators/csrf.py", line 65, in _view_wrapper
    return view_func(request, *args, **kwargs)
  File "/home/rashid/.cache/pypoetry/virtualenvs/cropgnosis-irOgLtvg-py3.10/lib/python3.10/site-packages/django/views/generic/base.py", line 104, in view
    return self.dispatch(request, *args, **kwargs)
  File "/home/rashid/.cache/pypoetry/virtualenvs/cropgnosis-irOgLtvg-py3.10/lib/python3.10/site-packages/rest_framework/views.py", line 509, in dispatch
    response = self.handle_exception(exc)
  File "/home/rashid/.cache/pypoetry/virtualenvs/cropgnosis-irOgLtvg-py3.10/lib/python3.10/site-packages/rest_framework/views.py", line 469, in handle_exception
    self.raise_uncaught_exception(exc)
  File "/home/rashid/.cache/pypoetry/virtualenvs/cropgnosis-irOgLtvg-py3.10/lib/python3.10/site-packages/rest_framework/views.py", line 480, in raise_uncaught_exception
    raise exc
  File "/home/rashid/.cache/pypoetry/virtualenvs/cropgnosis-irOgLtvg-py3.10/lib/python3.10/site-packages/rest_framework/views.py", line 506, in dispatch
    response = handler(request, *args, **kwargs)
  File "/home/rashid/Projects/CropGnosis/apps/subscription/views/customer_views.py", line 24, in post
    self.error_message("subscription_plan is required")
AttributeError: 'SubscriptionCheckOut' object has no attribute 'error_message'
[27/Mar/2024 06:51:15] ERROR [django.request:241] Internal Server Error: /api/subscription/subscription-check-out
Traceback (most recent call last):
  File "/home/rashid/.cache/pypoetry/virtualenvs/cropgnosis-irOgLtvg-py3.10/lib/python3.10/site-packages/django/core/handlers/exception.py", line 55, in inner
    response = get_response(request)
  File "/home/rashid/.cache/pypoetry/virtualenvs/cropgnosis-irOgLtvg-py3.10/lib/python3.10/site-packages/django/core/handlers/base.py", line 197, in _get_response
    response = wrapped_callback(request, *callback_args, **callback_kwargs)
  File "/home/rashid/.cache/pypoetry/virtualenvs/cropgnosis-irOgLtvg-py3.10/lib/python3.10/site-packages/django/views/decorators/csrf.py", line 65, in _view_wrapper
    return view_func(request, *args, **kwargs)
  File "/home/rashid/.cache/pypoetry/virtualenvs/cropgnosis-irOgLtvg-py3.10/lib/python3.10/site-packages/django/views/generic/base.py", line 104, in view
    return self.dispatch(request, *args, **kwargs)
  File "/home/rashid/.cache/pypoetry/virtualenvs/cropgnosis-irOgLtvg-py3.10/lib/python3.10/site-packages/rest_framework/views.py", line 509, in dispatch
    response = self.handle_exception(exc)
  File "/home/rashid/.cache/pypoetry/virtualenvs/cropgnosis-irOgLtvg-py3.10/lib/python3.10/site-packages/rest_framework/views.py", line 469, in handle_exception
    self.raise_uncaught_exception(exc)
  File "/home/rashid/.cache/pypoetry/virtualenvs/cropgnosis-irOgLtvg-py3.10/lib/python3.10/site-packages/rest_framework/views.py", line 480, in raise_uncaught_exception
    raise exc
  File "/home/rashid/.cache/pypoetry/virtualenvs/cropgnosis-irOgLtvg-py3.10/lib/python3.10/site-packages/rest_framework/views.py", line 506, in dispatch
    response = handler(request, *args, **kwargs)
  File "/home/rashid/Projects/CropGnosis/apps/subscription/views/customer_views.py", line 24, in post
    self.error_message("subscription_plan is required")
AttributeError: 'SubscriptionCheckOut' object has no attribute 'error_message'
[27/Mar/2024 06:52:22] ERROR [django.request:241] Internal Server Error: /api/subscription/subscription-check-out
Traceback (most recent call last):
  File "/home/rashid/.cache/pypoetry/virtualenvs/cropgnosis-irOgLtvg-py3.10/lib/python3.10/site-packages/django/core/handlers/exception.py", line 55, in inner
    response = get_response(request)
  File "/home/rashid/.cache/pypoetry/virtualenvs/cropgnosis-irOgLtvg-py3.10/lib/python3.10/site-packages/django/core/handlers/base.py", line 197, in _get_response
    response = wrapped_callback(request, *callback_args, **callback_kwargs)
  File "/home/rashid/.cache/pypoetry/virtualenvs/cropgnosis-irOgLtvg-py3.10/lib/python3.10/site-packages/django/views/decorators/csrf.py", line 65, in _view_wrapper
    return view_func(request, *args, **kwargs)
  File "/home/rashid/.cache/pypoetry/virtualenvs/cropgnosis-irOgLtvg-py3.10/lib/python3.10/site-packages/django/views/generic/base.py", line 104, in view
    return self.dispatch(request, *args, **kwargs)
  File "/home/rashid/.cache/pypoetry/virtualenvs/cropgnosis-irOgLtvg-py3.10/lib/python3.10/site-packages/rest_framework/views.py", line 509, in dispatch
    response = self.handle_exception(exc)
  File "/home/rashid/.cache/pypoetry/virtualenvs/cropgnosis-irOgLtvg-py3.10/lib/python3.10/site-packages/rest_framework/views.py", line 469, in handle_exception
    self.raise_uncaught_exception(exc)
  File "/home/rashid/.cache/pypoetry/virtualenvs/cropgnosis-irOgLtvg-py3.10/lib/python3.10/site-packages/rest_framework/views.py", line 480, in raise_uncaught_exception
    raise exc
  File "/home/rashid/.cache/pypoetry/virtualenvs/cropgnosis-irOgLtvg-py3.10/lib/python3.10/site-packages/rest_framework/views.py", line 506, in dispatch
    response = handler(request, *args, **kwargs)
  File "/home/rashid/Projects/CropGnosis/apps/subscription/views/customer_views.py", line 24, in post
    self.error_message("subscription_plan is required")
AttributeError: 'SubscriptionCheckOut' object has no attribute 'error_message'
[27/Mar/2024 06:53:18] ERROR [django.request:241] Internal Server Error: /api/subscription/subscription-check-out
Traceback (most recent call last):
  File "/home/rashid/.cache/pypoetry/virtualenvs/cropgnosis-irOgLtvg-py3.10/lib/python3.10/site-packages/django/core/handlers/exception.py", line 55, in inner
    response = get_response(request)
  File "/home/rashid/.cache/pypoetry/virtualenvs/cropgnosis-irOgLtvg-py3.10/lib/python3.10/site-packages/django/core/handlers/base.py", line 197, in _get_response
    response = wrapped_callback(request, *callback_args, **callback_kwargs)
  File "/home/rashid/.cache/pypoetry/virtualenvs/cropgnosis-irOgLtvg-py3.10/lib/python3.10/site-packages/django/views/decorators/csrf.py", line 65, in _view_wrapper
    return view_func(request, *args, **kwargs)
  File "/home/rashid/.cache/pypoetry/virtualenvs/cropgnosis-irOgLtvg-py3.10/lib/python3.10/site-packages/django/views/generic/base.py", line 104, in view
    return self.dispatch(request, *args, **kwargs)
  File "/home/rashid/.cache/pypoetry/virtualenvs/cropgnosis-irOgLtvg-py3.10/lib/python3.10/site-packages/rest_framework/views.py", line 511, in dispatch
    self.response = self.finalize_response(request, response, *args, **kwargs)
  File "/home/rashid/.cache/pypoetry/virtualenvs/cropgnosis-irOgLtvg-py3.10/lib/python3.10/site-packages/rest_framework/views.py", line 423, in finalize_response
    assert isinstance(response, HttpResponseBase), (
AssertionError: Expected a `Response`, `HttpResponse` or `HttpStreamingResponse` to be returned from the view, but received a `<class 'type'>`
[27/Mar/2024 06:53:31] ERROR [django.request:241] Internal Server Error: /api/subscription/subscription-check-out
Traceback (most recent call last):
  File "/home/rashid/.cache/pypoetry/virtualenvs/cropgnosis-irOgLtvg-py3.10/lib/python3.10/site-packages/django/core/handlers/exception.py", line 55, in inner
    response = get_response(request)
  File "/home/rashid/.cache/pypoetry/virtualenvs/cropgnosis-irOgLtvg-py3.10/lib/python3.10/site-packages/django/core/handlers/base.py", line 197, in _get_response
    response = wrapped_callback(request, *callback_args, **callback_kwargs)
  File "/home/rashid/.cache/pypoetry/virtualenvs/cropgnosis-irOgLtvg-py3.10/lib/python3.10/site-packages/django/views/decorators/csrf.py", line 65, in _view_wrapper
    return view_func(request, *args, **kwargs)
  File "/home/rashid/.cache/pypoetry/virtualenvs/cropgnosis-irOgLtvg-py3.10/lib/python3.10/site-packages/django/views/generic/base.py", line 104, in view
    return self.dispatch(request, *args, **kwargs)
  File "/home/rashid/.cache/pypoetry/virtualenvs/cropgnosis-irOgLtvg-py3.10/lib/python3.10/site-packages/rest_framework/views.py", line 511, in dispatch
    self.response = self.finalize_response(request, response, *args, **kwargs)
  File "/home/rashid/.cache/pypoetry/virtualenvs/cropgnosis-irOgLtvg-py3.10/lib/python3.10/site-packages/rest_framework/views.py", line 423, in finalize_response
    assert isinstance(response, HttpResponseBase), (
AssertionError: Expected a `Response`, `HttpResponse` or `HttpStreamingResponse` to be returned from the view, but received a `<class 'type'>`
[27/Mar/2024 06:54:01] WARNING [django.request:241] Bad Request: /api/subscription/subscription-check-out
[27/Mar/2024 06:59:10] ERROR [django.request:241] Internal Server Error: /api/subscription/subscription-check-out
[27/Mar/2024 06:59:35] WARNING [django.request:241] Not Found: /
[27/Mar/2024 07:00:23] ERROR [django.request:241] Internal Server Error: /api/subscription/subscription-check-out
[27/Mar/2024 07:25:55] ERROR [django.request:241] Internal Server Error: /api/subscription/subscription-check-out
Traceback (most recent call last):
  File "/home/rashid/.cache/pypoetry/virtualenvs/cropgnosis-irOgLtvg-py3.10/lib/python3.10/site-packages/django/core/handlers/exception.py", line 55, in inner
    response = get_response(request)
  File "/home/rashid/.cache/pypoetry/virtualenvs/cropgnosis-irOgLtvg-py3.10/lib/python3.10/site-packages/django/core/handlers/base.py", line 197, in _get_response
    response = wrapped_callback(request, *callback_args, **callback_kwargs)
  File "/home/rashid/.cache/pypoetry/virtualenvs/cropgnosis-irOgLtvg-py3.10/lib/python3.10/site-packages/django/views/decorators/csrf.py", line 65, in _view_wrapper
    return view_func(request, *args, **kwargs)
  File "/home/rashid/.cache/pypoetry/virtualenvs/cropgnosis-irOgLtvg-py3.10/lib/python3.10/site-packages/django/views/generic/base.py", line 104, in view
    return self.dispatch(request, *args, **kwargs)
  File "/home/rashid/.cache/pypoetry/virtualenvs/cropgnosis-irOgLtvg-py3.10/lib/python3.10/site-packages/rest_framework/views.py", line 509, in dispatch
    response = self.handle_exception(exc)
  File "/home/rashid/.cache/pypoetry/virtualenvs/cropgnosis-irOgLtvg-py3.10/lib/python3.10/site-packages/rest_framework/views.py", line 469, in handle_exception
    self.raise_uncaught_exception(exc)
  File "/home/rashid/.cache/pypoetry/virtualenvs/cropgnosis-irOgLtvg-py3.10/lib/python3.10/site-packages/rest_framework/views.py", line 480, in raise_uncaught_exception
    raise exc
  File "/home/rashid/.cache/pypoetry/virtualenvs/cropgnosis-irOgLtvg-py3.10/lib/python3.10/site-packages/rest_framework/views.py", line 506, in dispatch
    response = handler(request, *args, **kwargs)
  File "/home/rashid/Projects/CropGnosis/apps/subscription/views/customer_views.py", line 33, in post
    transaction = PaymentTransactions.objects.create(
  File "/home/rashid/.cache/pypoetry/virtualenvs/cropgnosis-irOgLtvg-py3.10/lib/python3.10/site-packages/django/db/models/manager.py", line 87, in manager_method
    return getattr(self.get_queryset(), name)(*args, **kwargs)
  File "/home/rashid/.cache/pypoetry/virtualenvs/cropgnosis-irOgLtvg-py3.10/lib/python3.10/site-packages/django/db/models/query.py", line 679, in create
    obj.save(force_insert=True, using=self.db)
  File "/home/rashid/Projects/CropGnosis/apps/subscription/models.py", line 102, in save
    super(PaymentTransactions,self).save(args, **kwargs)
TypeError: Model.save() got multiple values for argument 'force_insert'
[27/Mar/2024 07:26:36] ERROR [django.request:241] Internal Server Error: /api/subscription/subscription-check-out
Traceback (most recent call last):
  File "/home/rashid/.cache/pypoetry/virtualenvs/cropgnosis-irOgLtvg-py3.10/lib/python3.10/site-packages/django/core/handlers/exception.py", line 55, in inner
    response = get_response(request)
  File "/home/rashid/.cache/pypoetry/virtualenvs/cropgnosis-irOgLtvg-py3.10/lib/python3.10/site-packages/django/core/handlers/base.py", line 197, in _get_response
    response = wrapped_callback(request, *callback_args, **callback_kwargs)
  File "/home/rashid/.cache/pypoetry/virtualenvs/cropgnosis-irOgLtvg-py3.10/lib/python3.10/site-packages/django/views/decorators/csrf.py", line 65, in _view_wrapper
    return view_func(request, *args, **kwargs)
  File "/home/rashid/.cache/pypoetry/virtualenvs/cropgnosis-irOgLtvg-py3.10/lib/python3.10/site-packages/django/views/generic/base.py", line 104, in view
    return self.dispatch(request, *args, **kwargs)
  File "/home/rashid/.cache/pypoetry/virtualenvs/cropgnosis-irOgLtvg-py3.10/lib/python3.10/site-packages/rest_framework/views.py", line 509, in dispatch
    response = self.handle_exception(exc)
  File "/home/rashid/.cache/pypoetry/virtualenvs/cropgnosis-irOgLtvg-py3.10/lib/python3.10/site-packages/rest_framework/views.py", line 469, in handle_exception
    self.raise_uncaught_exception(exc)
  File "/home/rashid/.cache/pypoetry/virtualenvs/cropgnosis-irOgLtvg-py3.10/lib/python3.10/site-packages/rest_framework/views.py", line 480, in raise_uncaught_exception
    raise exc
  File "/home/rashid/.cache/pypoetry/virtualenvs/cropgnosis-irOgLtvg-py3.10/lib/python3.10/site-packages/rest_framework/views.py", line 506, in dispatch
    response = handler(request, *args, **kwargs)
  File "/home/rashid/Projects/CropGnosis/apps/subscription/views/customer_views.py", line 33, in post
    transaction = PaymentTransactions.objects.create(
  File "/home/rashid/.cache/pypoetry/virtualenvs/cropgnosis-irOgLtvg-py3.10/lib/python3.10/site-packages/django/db/models/manager.py", line 87, in manager_method
    return getattr(self.get_queryset(), name)(*args, **kwargs)
  File "/home/rashid/.cache/pypoetry/virtualenvs/cropgnosis-irOgLtvg-py3.10/lib/python3.10/site-packages/django/db/models/query.py", line 679, in create
    obj.save(force_insert=True, using=self.db)
  File "/home/rashid/Projects/CropGnosis/apps/subscription/models.py", line 102, in save
    super(PaymentTransactions,self).save(args, **kwargs)
TypeError: Model.save() got multiple values for argument 'force_insert'
[27/Mar/2024 07:31:13] ERROR [django.request:241] Internal Server Error: /api/subscription/subscription-check-out
[27/Mar/2024 07:57:14] WARNING [django.request:241] Not Found: /api/main/verify-scrubbing-logs
[27/Mar/2024 08:27:47] ERROR [django.request:241] Internal Server Error: /api/subscription/subscription-check-out
[27/Mar/2024 08:32:23] ERROR [django.request:241] Internal Server Error: /api/subscription/subscription-check-out
[27/Mar/2024 08:35:57] WARNING [django.request:241] Not Found: /favicon.ico
[27/Mar/2024 08:36:26] ERROR [django.request:241] Internal Server Error: /api/subscription/subscription-check-out
[27/Mar/2024 08:56:12] ERROR [django.request:241] Internal Server Error: /api/subscription/subscription-check-out
[27/Mar/2024 09:02:48] ERROR [django.request:241] Internal Server Error: /api/subscription/subscription-check-out
[27/Mar/2024 09:03:16] ERROR [django.request:241] Internal Server Error: /api/subscription/subscription-check-out
[27/Mar/2024 09:13:06] ERROR [django.request:241] Internal Server Error: /api/subscription/subscription-check-out
[27/Mar/2024 09:13:51] ERROR [django.request:241] Internal Server Error: /api/subscription/subscription-check-out
[27/Mar/2024 09:14:51] ERROR [django.request:241] Internal Server Error: /api/subscription/subscription-check-out
[30/Mar/2024 03:22:23] WARNING [django.request:241] Unauthorized: /api/subscription/subscription-check-out
[30/Mar/2024 03:23:57] WARNING [django.request:241] Unauthorized: /api/auth/customer/login
[30/Mar/2024 03:26:03] WARNING [django.request:241] Not Found: /
[30/Mar/2024 03:26:03] WARNING [django.request:241] Not Found: /favicon.ico
[30/Mar/2024 03:26:10] WARNING [django.request:241] Not Found: /subscription/subscription-check-out
[30/Mar/2024 03:26:32] WARNING [django.request:241] Unauthorized: /api/subscription/subscription-check-out
[30/Mar/2024 03:32:18] WARNING [django.request:241] Unauthorized: /api/subscription/subscription-check-out
[30/Mar/2024 03:34:15] WARNING [django.request:241] Unauthorized: /api/subscription/subscription-check-out
[30/Mar/2024 03:34:17] WARNING [django.request:241] Unauthorized: /api/subscription/subscription-check-out
[30/Mar/2024 03:36:50] WARNING [django.request:241] Unauthorized: /api/subscription/subscription-check-out
[30/Mar/2024 03:36:52] WARNING [django.request:241] Unauthorized: /api/subscription/subscription-check-out
[30/Mar/2024 03:36:59] WARNING [django.request:241] Unauthorized: /api/subscription/subscription-check-out
[30/Mar/2024 03:38:12] WARNING [django.request:241] Bad Request: /api/subscription/subscription-check-out
[30/Mar/2024 03:38:27] WARNING [django.request:241] Not Found: /
[30/Mar/2024 05:56:34] WARNING [django.request:241] Not Found: /api/api/common/base-plans
[30/Mar/2024 05:58:17] ERROR [django.request:241] Internal Server Error: /api/subscription/subscription-check-out
[30/Mar/2024 07:10:52] WARNING [django.request:241] Not Found: /
[30/Mar/2024 07:11:20] WARNING [django.request:241] Not Found: /api/subscription/style.css
[30/Mar/2024 07:11:23] WARNING [django.request:241] Bad Request: /api/subscription/subscription-check-out
[30/Mar/2024 07:15:05] WARNING [django.request:241] Not Found: /api/subscription/style.css
[30/Mar/2024 07:15:07] ERROR [django.request:241] Internal Server Error: /api/subscription/subscription-check-out
[30/Mar/2024 07:18:40] WARNING [django.request:241] Bad Request: /api/auth/customer/address
[30/Mar/2024 07:19:15] WARNING [django.request:241] Not Found: /api/subscription/style.css
[30/Mar/2024 07:20:41] WARNING [django.request:241] Method Not Allowed: /api/subscription/payment-success-callback
[30/Mar/2024 07:23:30] WARNING [django.request:241] Not Found: /api/subscription/style.css
[30/Mar/2024 07:25:06] WARNING [django.request:241] Method Not Allowed: /api/subscription/payment-success-callback
[30/Mar/2024 07:25:45] WARNING [django.request:241] Not Found: /api/subscription/style.css
[30/Mar/2024 11:55:41] WARNING [django.request:241] Not Found: /api/subscription/check-out
[30/Mar/2024 11:55:43] WARNING [django.request:241] Not Found: /api/subscription/check-out
[30/Mar/2024 11:55:51] WARNING [django.request:241] Not Found: /api/subscription/check-out
[30/Mar/2024 11:56:06] WARNING [django.request:241] Not Found: /api/subscription/style.css
[30/Mar/2024 11:56:09] ERROR [django.request:241] Internal Server Error: /api/subscription/subscription-check-out
[30/Mar/2024 12:02:37] WARNING [django.request:241] Not Found: /api/subscription/style.css
[30/Mar/2024 12:05:48] WARNING [django.request:241] Not Found: /api/subscription/style.css
[31/Mar/2024 06:03:13] WARNING [django.request:241] Not Found: /
[31/Mar/2024 09:17:30] WARNING [django.request:241] Not Found: /
[31/Mar/2024 09:17:43] ERROR [django.request:241] Internal Server Error: /admin/authorization/mentorsubscriptions/
Traceback (most recent call last):
  File "/home/rashid/.cache/pypoetry/virtualenvs/cropgnosis-p5HYragw-py3.11/lib/python3.11/site-packages/django/db/backends/utils.py", line 105, in _execute
    return self.cursor.execute(sql, params)
           ^^^^^^^^^^^^^^^^^^^^^^^^^^^^^^^^
psycopg2.errors.UndefinedTable: relation "authorization_mentorbasesubscriptionplans" does not exist
LINE 1: ...OM "authorization_mentorsubscriptions" INNER JOIN "authoriza...
                                                             ^


The above exception was the direct cause of the following exception:

Traceback (most recent call last):
  File "/home/rashid/.cache/pypoetry/virtualenvs/cropgnosis-p5HYragw-py3.11/lib/python3.11/site-packages/django/core/handlers/exception.py", line 55, in inner
    response = get_response(request)
               ^^^^^^^^^^^^^^^^^^^^^
  File "/home/rashid/.cache/pypoetry/virtualenvs/cropgnosis-p5HYragw-py3.11/lib/python3.11/site-packages/django/core/handlers/base.py", line 197, in _get_response
    response = wrapped_callback(request, *callback_args, **callback_kwargs)
               ^^^^^^^^^^^^^^^^^^^^^^^^^^^^^^^^^^^^^^^^^^^^^^^^^^^^^^^^^^^^
  File "/home/rashid/.cache/pypoetry/virtualenvs/cropgnosis-p5HYragw-py3.11/lib/python3.11/site-packages/django/contrib/admin/options.py", line 715, in wrapper
    return self.admin_site.admin_view(view)(*args, **kwargs)
           ^^^^^^^^^^^^^^^^^^^^^^^^^^^^^^^^^^^^^^^^^^^^^^^^^
  File "/home/rashid/.cache/pypoetry/virtualenvs/cropgnosis-p5HYragw-py3.11/lib/python3.11/site-packages/django/utils/decorators.py", line 188, in _view_wrapper
    result = _process_exception(request, e)
             ^^^^^^^^^^^^^^^^^^^^^^^^^^^^^^
  File "/home/rashid/.cache/pypoetry/virtualenvs/cropgnosis-p5HYragw-py3.11/lib/python3.11/site-packages/django/utils/decorators.py", line 186, in _view_wrapper
    response = view_func(request, *args, **kwargs)
               ^^^^^^^^^^^^^^^^^^^^^^^^^^^^^^^^^^^
  File "/home/rashid/.cache/pypoetry/virtualenvs/cropgnosis-p5HYragw-py3.11/lib/python3.11/site-packages/django/views/decorators/cache.py", line 80, in _view_wrapper
    response = view_func(request, *args, **kwargs)
               ^^^^^^^^^^^^^^^^^^^^^^^^^^^^^^^^^^^
  File "/home/rashid/.cache/pypoetry/virtualenvs/cropgnosis-p5HYragw-py3.11/lib/python3.11/site-packages/django/contrib/admin/sites.py", line 240, in inner
    return view(request, *args, **kwargs)
           ^^^^^^^^^^^^^^^^^^^^^^^^^^^^^^
  File "/home/rashid/.cache/pypoetry/virtualenvs/cropgnosis-p5HYragw-py3.11/lib/python3.11/site-packages/django/utils/decorators.py", line 48, in _wrapper
    return bound_method(*args, **kwargs)
           ^^^^^^^^^^^^^^^^^^^^^^^^^^^^^
  File "/home/rashid/.cache/pypoetry/virtualenvs/cropgnosis-p5HYragw-py3.11/lib/python3.11/site-packages/django/utils/decorators.py", line 188, in _view_wrapper
    result = _process_exception(request, e)
             ^^^^^^^^^^^^^^^^^^^^^^^^^^^^^^
  File "/home/rashid/.cache/pypoetry/virtualenvs/cropgnosis-p5HYragw-py3.11/lib/python3.11/site-packages/django/utils/decorators.py", line 186, in _view_wrapper
    response = view_func(request, *args, **kwargs)
               ^^^^^^^^^^^^^^^^^^^^^^^^^^^^^^^^^^^
  File "/home/rashid/.cache/pypoetry/virtualenvs/cropgnosis-p5HYragw-py3.11/lib/python3.11/site-packages/django/contrib/admin/options.py", line 2123, in changelist_view
    "selection_note": _("0 of %(cnt)s selected") % {"cnt": len(cl.result_list)},
                                                           ^^^^^^^^^^^^^^^^^^^
  File "/home/rashid/.cache/pypoetry/virtualenvs/cropgnosis-p5HYragw-py3.11/lib/python3.11/site-packages/django/db/models/query.py", line 382, in __len__
    self._fetch_all()
  File "/home/rashid/.cache/pypoetry/virtualenvs/cropgnosis-p5HYragw-py3.11/lib/python3.11/site-packages/django/db/models/query.py", line 1928, in _fetch_all
    self._result_cache = list(self._iterable_class(self))
                         ^^^^^^^^^^^^^^^^^^^^^^^^^^^^^^^^
  File "/home/rashid/.cache/pypoetry/virtualenvs/cropgnosis-p5HYragw-py3.11/lib/python3.11/site-packages/django/db/models/query.py", line 91, in __iter__
    results = compiler.execute_sql(
              ^^^^^^^^^^^^^^^^^^^^^
  File "/home/rashid/.cache/pypoetry/virtualenvs/cropgnosis-p5HYragw-py3.11/lib/python3.11/site-packages/django/db/models/sql/compiler.py", line 1562, in execute_sql
    cursor.execute(sql, params)
  File "/home/rashid/.cache/pypoetry/virtualenvs/cropgnosis-p5HYragw-py3.11/lib/python3.11/site-packages/django/db/backends/utils.py", line 122, in execute
    return super().execute(sql, params)
           ^^^^^^^^^^^^^^^^^^^^^^^^^^^^
  File "/home/rashid/.cache/pypoetry/virtualenvs/cropgnosis-p5HYragw-py3.11/lib/python3.11/site-packages/django/db/backends/utils.py", line 79, in execute
    return self._execute_with_wrappers(
           ^^^^^^^^^^^^^^^^^^^^^^^^^^^^
  File "/home/rashid/.cache/pypoetry/virtualenvs/cropgnosis-p5HYragw-py3.11/lib/python3.11/site-packages/django/db/backends/utils.py", line 92, in _execute_with_wrappers
    return executor(sql, params, many, context)
           ^^^^^^^^^^^^^^^^^^^^^^^^^^^^^^^^^^^^
  File "/home/rashid/.cache/pypoetry/virtualenvs/cropgnosis-p5HYragw-py3.11/lib/python3.11/site-packages/django/db/backends/utils.py", line 100, in _execute
    with self.db.wrap_database_errors:
  File "/home/rashid/.cache/pypoetry/virtualenvs/cropgnosis-p5HYragw-py3.11/lib/python3.11/site-packages/django/db/utils.py", line 91, in __exit__
    raise dj_exc_value.with_traceback(traceback) from exc_value
  File "/home/rashid/.cache/pypoetry/virtualenvs/cropgnosis-p5HYragw-py3.11/lib/python3.11/site-packages/django/db/backends/utils.py", line 105, in _execute
    return self.cursor.execute(sql, params)
           ^^^^^^^^^^^^^^^^^^^^^^^^^^^^^^^^
django.db.utils.ProgrammingError: relation "authorization_mentorbasesubscriptionplans" does not exist
LINE 1: ...OM "authorization_mentorsubscriptions" INNER JOIN "authoriza...
                                                             ^

[31/Mar/2024 09:18:07] ERROR [django.request:241] Internal Server Error: /admin/subscription/basesubscriptionplans/
Traceback (most recent call last):
  File "/home/rashid/.cache/pypoetry/virtualenvs/cropgnosis-p5HYragw-py3.11/lib/python3.11/site-packages/django/db/backends/utils.py", line 105, in _execute
    return self.cursor.execute(sql, params)
           ^^^^^^^^^^^^^^^^^^^^^^^^^^^^^^^^
psycopg2.errors.UndefinedColumn: column subscription_paymenttransactions.mentor_plan_id does not exist
LINE 1: ...", "subscription_paymenttransactions"."addon_id", "subscript...
                                                             ^


The above exception was the direct cause of the following exception:

Traceback (most recent call last):
  File "/home/rashid/.cache/pypoetry/virtualenvs/cropgnosis-p5HYragw-py3.11/lib/python3.11/site-packages/django/core/handlers/exception.py", line 55, in inner
    response = get_response(request)
               ^^^^^^^^^^^^^^^^^^^^^
  File "/home/rashid/.cache/pypoetry/virtualenvs/cropgnosis-p5HYragw-py3.11/lib/python3.11/site-packages/django/core/handlers/base.py", line 197, in _get_response
    response = wrapped_callback(request, *callback_args, **callback_kwargs)
               ^^^^^^^^^^^^^^^^^^^^^^^^^^^^^^^^^^^^^^^^^^^^^^^^^^^^^^^^^^^^
  File "/home/rashid/.cache/pypoetry/virtualenvs/cropgnosis-p5HYragw-py3.11/lib/python3.11/site-packages/django/contrib/admin/options.py", line 715, in wrapper
    return self.admin_site.admin_view(view)(*args, **kwargs)
           ^^^^^^^^^^^^^^^^^^^^^^^^^^^^^^^^^^^^^^^^^^^^^^^^^
  File "/home/rashid/.cache/pypoetry/virtualenvs/cropgnosis-p5HYragw-py3.11/lib/python3.11/site-packages/django/utils/decorators.py", line 188, in _view_wrapper
    result = _process_exception(request, e)
             ^^^^^^^^^^^^^^^^^^^^^^^^^^^^^^
  File "/home/rashid/.cache/pypoetry/virtualenvs/cropgnosis-p5HYragw-py3.11/lib/python3.11/site-packages/django/utils/decorators.py", line 186, in _view_wrapper
    response = view_func(request, *args, **kwargs)
               ^^^^^^^^^^^^^^^^^^^^^^^^^^^^^^^^^^^
  File "/home/rashid/.cache/pypoetry/virtualenvs/cropgnosis-p5HYragw-py3.11/lib/python3.11/site-packages/django/views/decorators/cache.py", line 80, in _view_wrapper
    response = view_func(request, *args, **kwargs)
               ^^^^^^^^^^^^^^^^^^^^^^^^^^^^^^^^^^^
  File "/home/rashid/.cache/pypoetry/virtualenvs/cropgnosis-p5HYragw-py3.11/lib/python3.11/site-packages/django/contrib/admin/sites.py", line 240, in inner
    return view(request, *args, **kwargs)
           ^^^^^^^^^^^^^^^^^^^^^^^^^^^^^^
  File "/home/rashid/.cache/pypoetry/virtualenvs/cropgnosis-p5HYragw-py3.11/lib/python3.11/site-packages/django/utils/decorators.py", line 48, in _wrapper
    return bound_method(*args, **kwargs)
           ^^^^^^^^^^^^^^^^^^^^^^^^^^^^^
  File "/home/rashid/.cache/pypoetry/virtualenvs/cropgnosis-p5HYragw-py3.11/lib/python3.11/site-packages/django/utils/decorators.py", line 188, in _view_wrapper
    result = _process_exception(request, e)
             ^^^^^^^^^^^^^^^^^^^^^^^^^^^^^^
  File "/home/rashid/.cache/pypoetry/virtualenvs/cropgnosis-p5HYragw-py3.11/lib/python3.11/site-packages/django/utils/decorators.py", line 186, in _view_wrapper
    response = view_func(request, *args, **kwargs)
               ^^^^^^^^^^^^^^^^^^^^^^^^^^^^^^^^^^^
  File "/home/rashid/.cache/pypoetry/virtualenvs/cropgnosis-p5HYragw-py3.11/lib/python3.11/site-packages/django/contrib/admin/options.py", line 2017, in changelist_view
    response = self.response_action(
               ^^^^^^^^^^^^^^^^^^^^^
  File "/home/rashid/.cache/pypoetry/virtualenvs/cropgnosis-p5HYragw-py3.11/lib/python3.11/site-packages/django/contrib/admin/options.py", line 1649, in response_action
    response = func(self, request, queryset)
               ^^^^^^^^^^^^^^^^^^^^^^^^^^^^^
  File "/home/rashid/.cache/pypoetry/virtualenvs/cropgnosis-p5HYragw-py3.11/lib/python3.11/site-packages/django/contrib/admin/actions.py", line 39, in delete_selected
    ) = modeladmin.get_deleted_objects(queryset, request)
        ^^^^^^^^^^^^^^^^^^^^^^^^^^^^^^^^^^^^^^^^^^^^^^^^^
  File "/home/rashid/.cache/pypoetry/virtualenvs/cropgnosis-p5HYragw-py3.11/lib/python3.11/site-packages/django/contrib/admin/options.py", line 2159, in get_deleted_objects
    return get_deleted_objects(objs, request, self.admin_site)
           ^^^^^^^^^^^^^^^^^^^^^^^^^^^^^^^^^^^^^^^^^^^^^^^^^^^
  File "/home/rashid/.cache/pypoetry/virtualenvs/cropgnosis-p5HYragw-py3.11/lib/python3.11/site-packages/django/contrib/admin/utils.py", line 137, in get_deleted_objects
    collector.collect(objs)
  File "/home/rashid/.cache/pypoetry/virtualenvs/cropgnosis-p5HYragw-py3.11/lib/python3.11/site-packages/django/contrib/admin/utils.py", line 204, in collect
    return super().collect(objs, source_attr=source_attr, **kwargs)
           ^^^^^^^^^^^^^^^^^^^^^^^^^^^^^^^^^^^^^^^^^^^^^^^^^^^^^^^^
  File "/home/rashid/.cache/pypoetry/virtualenvs/cropgnosis-p5HYragw-py3.11/lib/python3.11/site-packages/django/db/models/deletion.py", line 348, in collect
    if getattr(on_delete, "lazy_sub_objs", False) or sub_objs:
  File "/home/rashid/.cache/pypoetry/virtualenvs/cropgnosis-p5HYragw-py3.11/lib/python3.11/site-packages/django/db/models/query.py", line 414, in __bool__
    self._fetch_all()
  File "/home/rashid/.cache/pypoetry/virtualenvs/cropgnosis-p5HYragw-py3.11/lib/python3.11/site-packages/django/db/models/query.py", line 1928, in _fetch_all
    self._result_cache = list(self._iterable_class(self))
                         ^^^^^^^^^^^^^^^^^^^^^^^^^^^^^^^^
  File "/home/rashid/.cache/pypoetry/virtualenvs/cropgnosis-p5HYragw-py3.11/lib/python3.11/site-packages/django/db/models/query.py", line 91, in __iter__
    results = compiler.execute_sql(
              ^^^^^^^^^^^^^^^^^^^^^
  File "/home/rashid/.cache/pypoetry/virtualenvs/cropgnosis-p5HYragw-py3.11/lib/python3.11/site-packages/django/db/models/sql/compiler.py", line 1562, in execute_sql
    cursor.execute(sql, params)
  File "/home/rashid/.cache/pypoetry/virtualenvs/cropgnosis-p5HYragw-py3.11/lib/python3.11/site-packages/django/db/backends/utils.py", line 122, in execute
    return super().execute(sql, params)
           ^^^^^^^^^^^^^^^^^^^^^^^^^^^^
  File "/home/rashid/.cache/pypoetry/virtualenvs/cropgnosis-p5HYragw-py3.11/lib/python3.11/site-packages/django/db/backends/utils.py", line 79, in execute
    return self._execute_with_wrappers(
           ^^^^^^^^^^^^^^^^^^^^^^^^^^^^
  File "/home/rashid/.cache/pypoetry/virtualenvs/cropgnosis-p5HYragw-py3.11/lib/python3.11/site-packages/django/db/backends/utils.py", line 92, in _execute_with_wrappers
    return executor(sql, params, many, context)
           ^^^^^^^^^^^^^^^^^^^^^^^^^^^^^^^^^^^^
  File "/home/rashid/.cache/pypoetry/virtualenvs/cropgnosis-p5HYragw-py3.11/lib/python3.11/site-packages/django/db/backends/utils.py", line 100, in _execute
    with self.db.wrap_database_errors:
  File "/home/rashid/.cache/pypoetry/virtualenvs/cropgnosis-p5HYragw-py3.11/lib/python3.11/site-packages/django/db/utils.py", line 91, in __exit__
    raise dj_exc_value.with_traceback(traceback) from exc_value
  File "/home/rashid/.cache/pypoetry/virtualenvs/cropgnosis-p5HYragw-py3.11/lib/python3.11/site-packages/django/db/backends/utils.py", line 105, in _execute
    return self.cursor.execute(sql, params)
           ^^^^^^^^^^^^^^^^^^^^^^^^^^^^^^^^
django.db.utils.ProgrammingError: column subscription_paymenttransactions.mentor_plan_id does not exist
LINE 1: ...", "subscription_paymenttransactions"."addon_id", "subscript...
                                                             ^

[31/Mar/2024 09:18:17] ERROR [django.request:241] Internal Server Error: /admin/subscription/basesubscriptionplans/
Traceback (most recent call last):
  File "/home/rashid/.cache/pypoetry/virtualenvs/cropgnosis-p5HYragw-py3.11/lib/python3.11/site-packages/django/db/backends/utils.py", line 105, in _execute
    return self.cursor.execute(sql, params)
           ^^^^^^^^^^^^^^^^^^^^^^^^^^^^^^^^
psycopg2.errors.UndefinedColumn: column subscription_paymenttransactions.mentor_plan_id does not exist
LINE 1: ...", "subscription_paymenttransactions"."addon_id", "subscript...
                                                             ^


The above exception was the direct cause of the following exception:

Traceback (most recent call last):
  File "/home/rashid/.cache/pypoetry/virtualenvs/cropgnosis-p5HYragw-py3.11/lib/python3.11/site-packages/django/core/handlers/exception.py", line 55, in inner
    response = get_response(request)
               ^^^^^^^^^^^^^^^^^^^^^
  File "/home/rashid/.cache/pypoetry/virtualenvs/cropgnosis-p5HYragw-py3.11/lib/python3.11/site-packages/django/core/handlers/base.py", line 197, in _get_response
    response = wrapped_callback(request, *callback_args, **callback_kwargs)
               ^^^^^^^^^^^^^^^^^^^^^^^^^^^^^^^^^^^^^^^^^^^^^^^^^^^^^^^^^^^^
  File "/home/rashid/.cache/pypoetry/virtualenvs/cropgnosis-p5HYragw-py3.11/lib/python3.11/site-packages/django/contrib/admin/options.py", line 715, in wrapper
    return self.admin_site.admin_view(view)(*args, **kwargs)
           ^^^^^^^^^^^^^^^^^^^^^^^^^^^^^^^^^^^^^^^^^^^^^^^^^
  File "/home/rashid/.cache/pypoetry/virtualenvs/cropgnosis-p5HYragw-py3.11/lib/python3.11/site-packages/django/utils/decorators.py", line 188, in _view_wrapper
    result = _process_exception(request, e)
             ^^^^^^^^^^^^^^^^^^^^^^^^^^^^^^
  File "/home/rashid/.cache/pypoetry/virtualenvs/cropgnosis-p5HYragw-py3.11/lib/python3.11/site-packages/django/utils/decorators.py", line 186, in _view_wrapper
    response = view_func(request, *args, **kwargs)
               ^^^^^^^^^^^^^^^^^^^^^^^^^^^^^^^^^^^
  File "/home/rashid/.cache/pypoetry/virtualenvs/cropgnosis-p5HYragw-py3.11/lib/python3.11/site-packages/django/views/decorators/cache.py", line 80, in _view_wrapper
    response = view_func(request, *args, **kwargs)
               ^^^^^^^^^^^^^^^^^^^^^^^^^^^^^^^^^^^
  File "/home/rashid/.cache/pypoetry/virtualenvs/cropgnosis-p5HYragw-py3.11/lib/python3.11/site-packages/django/contrib/admin/sites.py", line 240, in inner
    return view(request, *args, **kwargs)
           ^^^^^^^^^^^^^^^^^^^^^^^^^^^^^^
  File "/home/rashid/.cache/pypoetry/virtualenvs/cropgnosis-p5HYragw-py3.11/lib/python3.11/site-packages/django/utils/decorators.py", line 48, in _wrapper
    return bound_method(*args, **kwargs)
           ^^^^^^^^^^^^^^^^^^^^^^^^^^^^^
  File "/home/rashid/.cache/pypoetry/virtualenvs/cropgnosis-p5HYragw-py3.11/lib/python3.11/site-packages/django/utils/decorators.py", line 188, in _view_wrapper
    result = _process_exception(request, e)
             ^^^^^^^^^^^^^^^^^^^^^^^^^^^^^^
  File "/home/rashid/.cache/pypoetry/virtualenvs/cropgnosis-p5HYragw-py3.11/lib/python3.11/site-packages/django/utils/decorators.py", line 186, in _view_wrapper
    response = view_func(request, *args, **kwargs)
               ^^^^^^^^^^^^^^^^^^^^^^^^^^^^^^^^^^^
  File "/home/rashid/.cache/pypoetry/virtualenvs/cropgnosis-p5HYragw-py3.11/lib/python3.11/site-packages/django/contrib/admin/options.py", line 2017, in changelist_view
    response = self.response_action(
               ^^^^^^^^^^^^^^^^^^^^^
  File "/home/rashid/.cache/pypoetry/virtualenvs/cropgnosis-p5HYragw-py3.11/lib/python3.11/site-packages/django/contrib/admin/options.py", line 1649, in response_action
    response = func(self, request, queryset)
               ^^^^^^^^^^^^^^^^^^^^^^^^^^^^^
  File "/home/rashid/.cache/pypoetry/virtualenvs/cropgnosis-p5HYragw-py3.11/lib/python3.11/site-packages/django/contrib/admin/actions.py", line 39, in delete_selected
    ) = modeladmin.get_deleted_objects(queryset, request)
        ^^^^^^^^^^^^^^^^^^^^^^^^^^^^^^^^^^^^^^^^^^^^^^^^^
  File "/home/rashid/.cache/pypoetry/virtualenvs/cropgnosis-p5HYragw-py3.11/lib/python3.11/site-packages/django/contrib/admin/options.py", line 2159, in get_deleted_objects
    return get_deleted_objects(objs, request, self.admin_site)
           ^^^^^^^^^^^^^^^^^^^^^^^^^^^^^^^^^^^^^^^^^^^^^^^^^^^
  File "/home/rashid/.cache/pypoetry/virtualenvs/cropgnosis-p5HYragw-py3.11/lib/python3.11/site-packages/django/contrib/admin/utils.py", line 137, in get_deleted_objects
    collector.collect(objs)
  File "/home/rashid/.cache/pypoetry/virtualenvs/cropgnosis-p5HYragw-py3.11/lib/python3.11/site-packages/django/contrib/admin/utils.py", line 204, in collect
    return super().collect(objs, source_attr=source_attr, **kwargs)
           ^^^^^^^^^^^^^^^^^^^^^^^^^^^^^^^^^^^^^^^^^^^^^^^^^^^^^^^^
  File "/home/rashid/.cache/pypoetry/virtualenvs/cropgnosis-p5HYragw-py3.11/lib/python3.11/site-packages/django/db/models/deletion.py", line 348, in collect
    if getattr(on_delete, "lazy_sub_objs", False) or sub_objs:
  File "/home/rashid/.cache/pypoetry/virtualenvs/cropgnosis-p5HYragw-py3.11/lib/python3.11/site-packages/django/db/models/query.py", line 414, in __bool__
    self._fetch_all()
  File "/home/rashid/.cache/pypoetry/virtualenvs/cropgnosis-p5HYragw-py3.11/lib/python3.11/site-packages/django/db/models/query.py", line 1928, in _fetch_all
    self._result_cache = list(self._iterable_class(self))
                         ^^^^^^^^^^^^^^^^^^^^^^^^^^^^^^^^
  File "/home/rashid/.cache/pypoetry/virtualenvs/cropgnosis-p5HYragw-py3.11/lib/python3.11/site-packages/django/db/models/query.py", line 91, in __iter__
    results = compiler.execute_sql(
              ^^^^^^^^^^^^^^^^^^^^^
  File "/home/rashid/.cache/pypoetry/virtualenvs/cropgnosis-p5HYragw-py3.11/lib/python3.11/site-packages/django/db/models/sql/compiler.py", line 1562, in execute_sql
    cursor.execute(sql, params)
  File "/home/rashid/.cache/pypoetry/virtualenvs/cropgnosis-p5HYragw-py3.11/lib/python3.11/site-packages/django/db/backends/utils.py", line 122, in execute
    return super().execute(sql, params)
           ^^^^^^^^^^^^^^^^^^^^^^^^^^^^
  File "/home/rashid/.cache/pypoetry/virtualenvs/cropgnosis-p5HYragw-py3.11/lib/python3.11/site-packages/django/db/backends/utils.py", line 79, in execute
    return self._execute_with_wrappers(
           ^^^^^^^^^^^^^^^^^^^^^^^^^^^^
  File "/home/rashid/.cache/pypoetry/virtualenvs/cropgnosis-p5HYragw-py3.11/lib/python3.11/site-packages/django/db/backends/utils.py", line 92, in _execute_with_wrappers
    return executor(sql, params, many, context)
           ^^^^^^^^^^^^^^^^^^^^^^^^^^^^^^^^^^^^
  File "/home/rashid/.cache/pypoetry/virtualenvs/cropgnosis-p5HYragw-py3.11/lib/python3.11/site-packages/django/db/backends/utils.py", line 100, in _execute
    with self.db.wrap_database_errors:
  File "/home/rashid/.cache/pypoetry/virtualenvs/cropgnosis-p5HYragw-py3.11/lib/python3.11/site-packages/django/db/utils.py", line 91, in __exit__
    raise dj_exc_value.with_traceback(traceback) from exc_value
  File "/home/rashid/.cache/pypoetry/virtualenvs/cropgnosis-p5HYragw-py3.11/lib/python3.11/site-packages/django/db/backends/utils.py", line 105, in _execute
    return self.cursor.execute(sql, params)
           ^^^^^^^^^^^^^^^^^^^^^^^^^^^^^^^^
django.db.utils.ProgrammingError: column subscription_paymenttransactions.mentor_plan_id does not exist
LINE 1: ...", "subscription_paymenttransactions"."addon_id", "subscript...
                                                             ^

[31/Mar/2024 09:18:29] ERROR [django.request:241] Internal Server Error: /admin/subscription/paymenttransactions/
Traceback (most recent call last):
  File "/home/rashid/.cache/pypoetry/virtualenvs/cropgnosis-p5HYragw-py3.11/lib/python3.11/site-packages/django/db/backends/utils.py", line 105, in _execute
    return self.cursor.execute(sql, params)
           ^^^^^^^^^^^^^^^^^^^^^^^^^^^^^^^^
psycopg2.errors.UndefinedColumn: column subscription_paymenttransactions.mentor_plan_id does not exist
LINE 1: ...", "subscription_paymenttransactions"."addon_id", "subscript...
                                                             ^


The above exception was the direct cause of the following exception:

Traceback (most recent call last):
  File "/home/rashid/.cache/pypoetry/virtualenvs/cropgnosis-p5HYragw-py3.11/lib/python3.11/site-packages/django/core/handlers/exception.py", line 55, in inner
    response = get_response(request)
               ^^^^^^^^^^^^^^^^^^^^^
  File "/home/rashid/.cache/pypoetry/virtualenvs/cropgnosis-p5HYragw-py3.11/lib/python3.11/site-packages/django/core/handlers/base.py", line 197, in _get_response
    response = wrapped_callback(request, *callback_args, **callback_kwargs)
               ^^^^^^^^^^^^^^^^^^^^^^^^^^^^^^^^^^^^^^^^^^^^^^^^^^^^^^^^^^^^
  File "/home/rashid/.cache/pypoetry/virtualenvs/cropgnosis-p5HYragw-py3.11/lib/python3.11/site-packages/django/contrib/admin/options.py", line 715, in wrapper
    return self.admin_site.admin_view(view)(*args, **kwargs)
           ^^^^^^^^^^^^^^^^^^^^^^^^^^^^^^^^^^^^^^^^^^^^^^^^^
  File "/home/rashid/.cache/pypoetry/virtualenvs/cropgnosis-p5HYragw-py3.11/lib/python3.11/site-packages/django/utils/decorators.py", line 188, in _view_wrapper
    result = _process_exception(request, e)
             ^^^^^^^^^^^^^^^^^^^^^^^^^^^^^^
  File "/home/rashid/.cache/pypoetry/virtualenvs/cropgnosis-p5HYragw-py3.11/lib/python3.11/site-packages/django/utils/decorators.py", line 186, in _view_wrapper
    response = view_func(request, *args, **kwargs)
               ^^^^^^^^^^^^^^^^^^^^^^^^^^^^^^^^^^^
  File "/home/rashid/.cache/pypoetry/virtualenvs/cropgnosis-p5HYragw-py3.11/lib/python3.11/site-packages/django/views/decorators/cache.py", line 80, in _view_wrapper
    response = view_func(request, *args, **kwargs)
               ^^^^^^^^^^^^^^^^^^^^^^^^^^^^^^^^^^^
  File "/home/rashid/.cache/pypoetry/virtualenvs/cropgnosis-p5HYragw-py3.11/lib/python3.11/site-packages/django/contrib/admin/sites.py", line 240, in inner
    return view(request, *args, **kwargs)
           ^^^^^^^^^^^^^^^^^^^^^^^^^^^^^^
  File "/home/rashid/.cache/pypoetry/virtualenvs/cropgnosis-p5HYragw-py3.11/lib/python3.11/site-packages/django/utils/decorators.py", line 48, in _wrapper
    return bound_method(*args, **kwargs)
           ^^^^^^^^^^^^^^^^^^^^^^^^^^^^^
  File "/home/rashid/.cache/pypoetry/virtualenvs/cropgnosis-p5HYragw-py3.11/lib/python3.11/site-packages/django/utils/decorators.py", line 188, in _view_wrapper
    result = _process_exception(request, e)
             ^^^^^^^^^^^^^^^^^^^^^^^^^^^^^^
  File "/home/rashid/.cache/pypoetry/virtualenvs/cropgnosis-p5HYragw-py3.11/lib/python3.11/site-packages/django/utils/decorators.py", line 186, in _view_wrapper
    response = view_func(request, *args, **kwargs)
               ^^^^^^^^^^^^^^^^^^^^^^^^^^^^^^^^^^^
  File "/home/rashid/.cache/pypoetry/virtualenvs/cropgnosis-p5HYragw-py3.11/lib/python3.11/site-packages/django/contrib/admin/options.py", line 2123, in changelist_view
    "selection_note": _("0 of %(cnt)s selected") % {"cnt": len(cl.result_list)},
                                                           ^^^^^^^^^^^^^^^^^^^
  File "/home/rashid/.cache/pypoetry/virtualenvs/cropgnosis-p5HYragw-py3.11/lib/python3.11/site-packages/django/db/models/query.py", line 382, in __len__
    self._fetch_all()
  File "/home/rashid/.cache/pypoetry/virtualenvs/cropgnosis-p5HYragw-py3.11/lib/python3.11/site-packages/django/db/models/query.py", line 1928, in _fetch_all
    self._result_cache = list(self._iterable_class(self))
                         ^^^^^^^^^^^^^^^^^^^^^^^^^^^^^^^^
  File "/home/rashid/.cache/pypoetry/virtualenvs/cropgnosis-p5HYragw-py3.11/lib/python3.11/site-packages/django/db/models/query.py", line 91, in __iter__
    results = compiler.execute_sql(
              ^^^^^^^^^^^^^^^^^^^^^
  File "/home/rashid/.cache/pypoetry/virtualenvs/cropgnosis-p5HYragw-py3.11/lib/python3.11/site-packages/django/db/models/sql/compiler.py", line 1562, in execute_sql
    cursor.execute(sql, params)
  File "/home/rashid/.cache/pypoetry/virtualenvs/cropgnosis-p5HYragw-py3.11/lib/python3.11/site-packages/django/db/backends/utils.py", line 122, in execute
    return super().execute(sql, params)
           ^^^^^^^^^^^^^^^^^^^^^^^^^^^^
  File "/home/rashid/.cache/pypoetry/virtualenvs/cropgnosis-p5HYragw-py3.11/lib/python3.11/site-packages/django/db/backends/utils.py", line 79, in execute
    return self._execute_with_wrappers(
           ^^^^^^^^^^^^^^^^^^^^^^^^^^^^
  File "/home/rashid/.cache/pypoetry/virtualenvs/cropgnosis-p5HYragw-py3.11/lib/python3.11/site-packages/django/db/backends/utils.py", line 92, in _execute_with_wrappers
    return executor(sql, params, many, context)
           ^^^^^^^^^^^^^^^^^^^^^^^^^^^^^^^^^^^^
  File "/home/rashid/.cache/pypoetry/virtualenvs/cropgnosis-p5HYragw-py3.11/lib/python3.11/site-packages/django/db/backends/utils.py", line 100, in _execute
    with self.db.wrap_database_errors:
  File "/home/rashid/.cache/pypoetry/virtualenvs/cropgnosis-p5HYragw-py3.11/lib/python3.11/site-packages/django/db/utils.py", line 91, in __exit__
    raise dj_exc_value.with_traceback(traceback) from exc_value
  File "/home/rashid/.cache/pypoetry/virtualenvs/cropgnosis-p5HYragw-py3.11/lib/python3.11/site-packages/django/db/backends/utils.py", line 105, in _execute
    return self.cursor.execute(sql, params)
           ^^^^^^^^^^^^^^^^^^^^^^^^^^^^^^^^
django.db.utils.ProgrammingError: column subscription_paymenttransactions.mentor_plan_id does not exist
LINE 1: ...", "subscription_paymenttransactions"."addon_id", "subscript...
                                                             ^

[31/Mar/2024 09:18:35] ERROR [django.request:241] Internal Server Error: /admin/subscription/paymenttransactions/
Traceback (most recent call last):
  File "/home/rashid/.cache/pypoetry/virtualenvs/cropgnosis-p5HYragw-py3.11/lib/python3.11/site-packages/django/db/backends/utils.py", line 105, in _execute
    return self.cursor.execute(sql, params)
           ^^^^^^^^^^^^^^^^^^^^^^^^^^^^^^^^
psycopg2.errors.UndefinedColumn: column subscription_paymenttransactions.mentor_plan_id does not exist
LINE 1: ...", "subscription_paymenttransactions"."addon_id", "subscript...
                                                             ^


The above exception was the direct cause of the following exception:

Traceback (most recent call last):
  File "/home/rashid/.cache/pypoetry/virtualenvs/cropgnosis-p5HYragw-py3.11/lib/python3.11/site-packages/django/core/handlers/exception.py", line 55, in inner
    response = get_response(request)
               ^^^^^^^^^^^^^^^^^^^^^
  File "/home/rashid/.cache/pypoetry/virtualenvs/cropgnosis-p5HYragw-py3.11/lib/python3.11/site-packages/django/core/handlers/base.py", line 197, in _get_response
    response = wrapped_callback(request, *callback_args, **callback_kwargs)
               ^^^^^^^^^^^^^^^^^^^^^^^^^^^^^^^^^^^^^^^^^^^^^^^^^^^^^^^^^^^^
  File "/home/rashid/.cache/pypoetry/virtualenvs/cropgnosis-p5HYragw-py3.11/lib/python3.11/site-packages/django/contrib/admin/options.py", line 715, in wrapper
    return self.admin_site.admin_view(view)(*args, **kwargs)
           ^^^^^^^^^^^^^^^^^^^^^^^^^^^^^^^^^^^^^^^^^^^^^^^^^
  File "/home/rashid/.cache/pypoetry/virtualenvs/cropgnosis-p5HYragw-py3.11/lib/python3.11/site-packages/django/utils/decorators.py", line 188, in _view_wrapper
    result = _process_exception(request, e)
             ^^^^^^^^^^^^^^^^^^^^^^^^^^^^^^
  File "/home/rashid/.cache/pypoetry/virtualenvs/cropgnosis-p5HYragw-py3.11/lib/python3.11/site-packages/django/utils/decorators.py", line 186, in _view_wrapper
    response = view_func(request, *args, **kwargs)
               ^^^^^^^^^^^^^^^^^^^^^^^^^^^^^^^^^^^
  File "/home/rashid/.cache/pypoetry/virtualenvs/cropgnosis-p5HYragw-py3.11/lib/python3.11/site-packages/django/views/decorators/cache.py", line 80, in _view_wrapper
    response = view_func(request, *args, **kwargs)
               ^^^^^^^^^^^^^^^^^^^^^^^^^^^^^^^^^^^
  File "/home/rashid/.cache/pypoetry/virtualenvs/cropgnosis-p5HYragw-py3.11/lib/python3.11/site-packages/django/contrib/admin/sites.py", line 240, in inner
    return view(request, *args, **kwargs)
           ^^^^^^^^^^^^^^^^^^^^^^^^^^^^^^
  File "/home/rashid/.cache/pypoetry/virtualenvs/cropgnosis-p5HYragw-py3.11/lib/python3.11/site-packages/django/utils/decorators.py", line 48, in _wrapper
    return bound_method(*args, **kwargs)
           ^^^^^^^^^^^^^^^^^^^^^^^^^^^^^
  File "/home/rashid/.cache/pypoetry/virtualenvs/cropgnosis-p5HYragw-py3.11/lib/python3.11/site-packages/django/utils/decorators.py", line 188, in _view_wrapper
    result = _process_exception(request, e)
             ^^^^^^^^^^^^^^^^^^^^^^^^^^^^^^
  File "/home/rashid/.cache/pypoetry/virtualenvs/cropgnosis-p5HYragw-py3.11/lib/python3.11/site-packages/django/utils/decorators.py", line 186, in _view_wrapper
    response = view_func(request, *args, **kwargs)
               ^^^^^^^^^^^^^^^^^^^^^^^^^^^^^^^^^^^
  File "/home/rashid/.cache/pypoetry/virtualenvs/cropgnosis-p5HYragw-py3.11/lib/python3.11/site-packages/django/contrib/admin/options.py", line 2123, in changelist_view
    "selection_note": _("0 of %(cnt)s selected") % {"cnt": len(cl.result_list)},
                                                           ^^^^^^^^^^^^^^^^^^^
  File "/home/rashid/.cache/pypoetry/virtualenvs/cropgnosis-p5HYragw-py3.11/lib/python3.11/site-packages/django/db/models/query.py", line 382, in __len__
    self._fetch_all()
  File "/home/rashid/.cache/pypoetry/virtualenvs/cropgnosis-p5HYragw-py3.11/lib/python3.11/site-packages/django/db/models/query.py", line 1928, in _fetch_all
    self._result_cache = list(self._iterable_class(self))
                         ^^^^^^^^^^^^^^^^^^^^^^^^^^^^^^^^
  File "/home/rashid/.cache/pypoetry/virtualenvs/cropgnosis-p5HYragw-py3.11/lib/python3.11/site-packages/django/db/models/query.py", line 91, in __iter__
    results = compiler.execute_sql(
              ^^^^^^^^^^^^^^^^^^^^^
  File "/home/rashid/.cache/pypoetry/virtualenvs/cropgnosis-p5HYragw-py3.11/lib/python3.11/site-packages/django/db/models/sql/compiler.py", line 1562, in execute_sql
    cursor.execute(sql, params)
  File "/home/rashid/.cache/pypoetry/virtualenvs/cropgnosis-p5HYragw-py3.11/lib/python3.11/site-packages/django/db/backends/utils.py", line 122, in execute
    return super().execute(sql, params)
           ^^^^^^^^^^^^^^^^^^^^^^^^^^^^
  File "/home/rashid/.cache/pypoetry/virtualenvs/cropgnosis-p5HYragw-py3.11/lib/python3.11/site-packages/django/db/backends/utils.py", line 79, in execute
    return self._execute_with_wrappers(
           ^^^^^^^^^^^^^^^^^^^^^^^^^^^^
  File "/home/rashid/.cache/pypoetry/virtualenvs/cropgnosis-p5HYragw-py3.11/lib/python3.11/site-packages/django/db/backends/utils.py", line 92, in _execute_with_wrappers
    return executor(sql, params, many, context)
           ^^^^^^^^^^^^^^^^^^^^^^^^^^^^^^^^^^^^
  File "/home/rashid/.cache/pypoetry/virtualenvs/cropgnosis-p5HYragw-py3.11/lib/python3.11/site-packages/django/db/backends/utils.py", line 100, in _execute
    with self.db.wrap_database_errors:
  File "/home/rashid/.cache/pypoetry/virtualenvs/cropgnosis-p5HYragw-py3.11/lib/python3.11/site-packages/django/db/utils.py", line 91, in __exit__
    raise dj_exc_value.with_traceback(traceback) from exc_value
  File "/home/rashid/.cache/pypoetry/virtualenvs/cropgnosis-p5HYragw-py3.11/lib/python3.11/site-packages/django/db/backends/utils.py", line 105, in _execute
    return self.cursor.execute(sql, params)
           ^^^^^^^^^^^^^^^^^^^^^^^^^^^^^^^^
django.db.utils.ProgrammingError: column subscription_paymenttransactions.mentor_plan_id does not exist
LINE 1: ...", "subscription_paymenttransactions"."addon_id", "subscript...
                                                             ^

[31/Mar/2024 09:43:03] WARNING [django.request:241] Not Found: /
[31/Mar/2024 15:10:41] WARNING [django.request:241] Not Found: /
[31/Mar/2024 15:15:44] WARNING [django.request:241] Not Found: /admim
[31/Mar/2024 15:15:46] WARNING [django.request:241] Not Found: /admim
[31/Mar/2024 15:19:44] WARNING [django.request:241] Not Found: /api/auth/customer/mentor-registration
[31/Mar/2024 15:22:30] WARNING [django.request:241] Not Found: /api/auth/mentor/mentor-registration
[31/Mar/2024 15:22:50] WARNING [django.request:241] Unauthorized: /api/auth/mentor/registration
[31/Mar/2024 15:23:28] WARNING [django.request:241] Forbidden: /api/auth/mentor/login
[31/Mar/2024 15:26:00] WARNING [django.request:241] Bad Request: /api/auth/mentor/add-basementorplan
[31/Mar/2024 15:28:01] WARNING [django.request:241] Bad Request: /api/auth/mentor/add-basementorplan
[31/Mar/2024 15:30:44] WARNING [django.request:241] Bad Request: /api/auth/mentor/add-basementorplan
[31/Mar/2024 15:33:54] ERROR [django.request:241] Internal Server Error: /admin/authorization/mentorsubscriptions/
Traceback (most recent call last):
  File "/home/rashid/.cache/pypoetry/virtualenvs/cropgnosis-p5HYragw-py3.11/lib/python3.11/site-packages/django/db/backends/utils.py", line 105, in _execute
    return self.cursor.execute(sql, params)
           ^^^^^^^^^^^^^^^^^^^^^^^^^^^^^^^^
psycopg2.errors.UndefinedColumn: column authorization_mentorbasesubscriptionplans.uuid does not exist
LINE 1: ...tion_mentorsubscriptions"."mentor_base_plan_id" = "authoriza...
                                                             ^
HINT:  Perhaps you meant to reference the column "authorization_mentorbasesubscriptionplans.id".


The above exception was the direct cause of the following exception:

Traceback (most recent call last):
  File "/home/rashid/.cache/pypoetry/virtualenvs/cropgnosis-p5HYragw-py3.11/lib/python3.11/site-packages/django/core/handlers/exception.py", line 55, in inner
    response = get_response(request)
               ^^^^^^^^^^^^^^^^^^^^^
  File "/home/rashid/.cache/pypoetry/virtualenvs/cropgnosis-p5HYragw-py3.11/lib/python3.11/site-packages/django/core/handlers/base.py", line 197, in _get_response
    response = wrapped_callback(request, *callback_args, **callback_kwargs)
               ^^^^^^^^^^^^^^^^^^^^^^^^^^^^^^^^^^^^^^^^^^^^^^^^^^^^^^^^^^^^
  File "/home/rashid/.cache/pypoetry/virtualenvs/cropgnosis-p5HYragw-py3.11/lib/python3.11/site-packages/django/contrib/admin/options.py", line 715, in wrapper
    return self.admin_site.admin_view(view)(*args, **kwargs)
           ^^^^^^^^^^^^^^^^^^^^^^^^^^^^^^^^^^^^^^^^^^^^^^^^^
  File "/home/rashid/.cache/pypoetry/virtualenvs/cropgnosis-p5HYragw-py3.11/lib/python3.11/site-packages/django/utils/decorators.py", line 188, in _view_wrapper
    result = _process_exception(request, e)
             ^^^^^^^^^^^^^^^^^^^^^^^^^^^^^^
  File "/home/rashid/.cache/pypoetry/virtualenvs/cropgnosis-p5HYragw-py3.11/lib/python3.11/site-packages/django/utils/decorators.py", line 186, in _view_wrapper
    response = view_func(request, *args, **kwargs)
               ^^^^^^^^^^^^^^^^^^^^^^^^^^^^^^^^^^^
  File "/home/rashid/.cache/pypoetry/virtualenvs/cropgnosis-p5HYragw-py3.11/lib/python3.11/site-packages/django/views/decorators/cache.py", line 80, in _view_wrapper
    response = view_func(request, *args, **kwargs)
               ^^^^^^^^^^^^^^^^^^^^^^^^^^^^^^^^^^^
  File "/home/rashid/.cache/pypoetry/virtualenvs/cropgnosis-p5HYragw-py3.11/lib/python3.11/site-packages/django/contrib/admin/sites.py", line 240, in inner
    return view(request, *args, **kwargs)
           ^^^^^^^^^^^^^^^^^^^^^^^^^^^^^^
  File "/home/rashid/.cache/pypoetry/virtualenvs/cropgnosis-p5HYragw-py3.11/lib/python3.11/site-packages/django/utils/decorators.py", line 48, in _wrapper
    return bound_method(*args, **kwargs)
           ^^^^^^^^^^^^^^^^^^^^^^^^^^^^^
  File "/home/rashid/.cache/pypoetry/virtualenvs/cropgnosis-p5HYragw-py3.11/lib/python3.11/site-packages/django/utils/decorators.py", line 188, in _view_wrapper
    result = _process_exception(request, e)
             ^^^^^^^^^^^^^^^^^^^^^^^^^^^^^^
  File "/home/rashid/.cache/pypoetry/virtualenvs/cropgnosis-p5HYragw-py3.11/lib/python3.11/site-packages/django/utils/decorators.py", line 186, in _view_wrapper
    response = view_func(request, *args, **kwargs)
               ^^^^^^^^^^^^^^^^^^^^^^^^^^^^^^^^^^^
  File "/home/rashid/.cache/pypoetry/virtualenvs/cropgnosis-p5HYragw-py3.11/lib/python3.11/site-packages/django/contrib/admin/options.py", line 2123, in changelist_view
    "selection_note": _("0 of %(cnt)s selected") % {"cnt": len(cl.result_list)},
                                                           ^^^^^^^^^^^^^^^^^^^
  File "/home/rashid/.cache/pypoetry/virtualenvs/cropgnosis-p5HYragw-py3.11/lib/python3.11/site-packages/django/db/models/query.py", line 382, in __len__
    self._fetch_all()
  File "/home/rashid/.cache/pypoetry/virtualenvs/cropgnosis-p5HYragw-py3.11/lib/python3.11/site-packages/django/db/models/query.py", line 1928, in _fetch_all
    self._result_cache = list(self._iterable_class(self))
                         ^^^^^^^^^^^^^^^^^^^^^^^^^^^^^^^^
  File "/home/rashid/.cache/pypoetry/virtualenvs/cropgnosis-p5HYragw-py3.11/lib/python3.11/site-packages/django/db/models/query.py", line 91, in __iter__
    results = compiler.execute_sql(
              ^^^^^^^^^^^^^^^^^^^^^
  File "/home/rashid/.cache/pypoetry/virtualenvs/cropgnosis-p5HYragw-py3.11/lib/python3.11/site-packages/django/db/models/sql/compiler.py", line 1562, in execute_sql
    cursor.execute(sql, params)
  File "/home/rashid/.cache/pypoetry/virtualenvs/cropgnosis-p5HYragw-py3.11/lib/python3.11/site-packages/django/db/backends/utils.py", line 122, in execute
    return super().execute(sql, params)
           ^^^^^^^^^^^^^^^^^^^^^^^^^^^^
  File "/home/rashid/.cache/pypoetry/virtualenvs/cropgnosis-p5HYragw-py3.11/lib/python3.11/site-packages/django/db/backends/utils.py", line 79, in execute
    return self._execute_with_wrappers(
           ^^^^^^^^^^^^^^^^^^^^^^^^^^^^
  File "/home/rashid/.cache/pypoetry/virtualenvs/cropgnosis-p5HYragw-py3.11/lib/python3.11/site-packages/django/db/backends/utils.py", line 92, in _execute_with_wrappers
    return executor(sql, params, many, context)
           ^^^^^^^^^^^^^^^^^^^^^^^^^^^^^^^^^^^^
  File "/home/rashid/.cache/pypoetry/virtualenvs/cropgnosis-p5HYragw-py3.11/lib/python3.11/site-packages/django/db/backends/utils.py", line 100, in _execute
    with self.db.wrap_database_errors:
  File "/home/rashid/.cache/pypoetry/virtualenvs/cropgnosis-p5HYragw-py3.11/lib/python3.11/site-packages/django/db/utils.py", line 91, in __exit__
    raise dj_exc_value.with_traceback(traceback) from exc_value
  File "/home/rashid/.cache/pypoetry/virtualenvs/cropgnosis-p5HYragw-py3.11/lib/python3.11/site-packages/django/db/backends/utils.py", line 105, in _execute
    return self.cursor.execute(sql, params)
           ^^^^^^^^^^^^^^^^^^^^^^^^^^^^^^^^
django.db.utils.ProgrammingError: column authorization_mentorbasesubscriptionplans.uuid does not exist
LINE 1: ...tion_mentorsubscriptions"."mentor_base_plan_id" = "authoriza...
                                                             ^
HINT:  Perhaps you meant to reference the column "authorization_mentorbasesubscriptionplans.id".

[31/Mar/2024 15:42:37] ERROR [django.request:241] Internal Server Error: /admin/authorization/mentorsubscriptions/
Traceback (most recent call last):
  File "/home/rashid/.cache/pypoetry/virtualenvs/cropgnosis-p5HYragw-py3.11/lib/python3.11/site-packages/django/db/backends/utils.py", line 105, in _execute
    return self.cursor.execute(sql, params)
           ^^^^^^^^^^^^^^^^^^^^^^^^^^^^^^^^
psycopg2.errors.UndefinedFunction: operator does not exist: bigint = uuid
LINE 1: ...zation_mentorsubscriptions"."mentor_base_plan_id" = "authori...
                                                             ^
HINT:  No operator matches the given name and argument types. You might need to add explicit type casts.


The above exception was the direct cause of the following exception:

Traceback (most recent call last):
  File "/home/rashid/.cache/pypoetry/virtualenvs/cropgnosis-p5HYragw-py3.11/lib/python3.11/site-packages/django/core/handlers/exception.py", line 55, in inner
    response = get_response(request)
               ^^^^^^^^^^^^^^^^^^^^^
  File "/home/rashid/.cache/pypoetry/virtualenvs/cropgnosis-p5HYragw-py3.11/lib/python3.11/site-packages/django/core/handlers/base.py", line 197, in _get_response
    response = wrapped_callback(request, *callback_args, **callback_kwargs)
               ^^^^^^^^^^^^^^^^^^^^^^^^^^^^^^^^^^^^^^^^^^^^^^^^^^^^^^^^^^^^
  File "/home/rashid/.cache/pypoetry/virtualenvs/cropgnosis-p5HYragw-py3.11/lib/python3.11/site-packages/django/contrib/admin/options.py", line 715, in wrapper
    return self.admin_site.admin_view(view)(*args, **kwargs)
           ^^^^^^^^^^^^^^^^^^^^^^^^^^^^^^^^^^^^^^^^^^^^^^^^^
  File "/home/rashid/.cache/pypoetry/virtualenvs/cropgnosis-p5HYragw-py3.11/lib/python3.11/site-packages/django/utils/decorators.py", line 188, in _view_wrapper
    result = _process_exception(request, e)
             ^^^^^^^^^^^^^^^^^^^^^^^^^^^^^^
  File "/home/rashid/.cache/pypoetry/virtualenvs/cropgnosis-p5HYragw-py3.11/lib/python3.11/site-packages/django/utils/decorators.py", line 186, in _view_wrapper
    response = view_func(request, *args, **kwargs)
               ^^^^^^^^^^^^^^^^^^^^^^^^^^^^^^^^^^^
  File "/home/rashid/.cache/pypoetry/virtualenvs/cropgnosis-p5HYragw-py3.11/lib/python3.11/site-packages/django/views/decorators/cache.py", line 80, in _view_wrapper
    response = view_func(request, *args, **kwargs)
               ^^^^^^^^^^^^^^^^^^^^^^^^^^^^^^^^^^^
  File "/home/rashid/.cache/pypoetry/virtualenvs/cropgnosis-p5HYragw-py3.11/lib/python3.11/site-packages/django/contrib/admin/sites.py", line 240, in inner
    return view(request, *args, **kwargs)
           ^^^^^^^^^^^^^^^^^^^^^^^^^^^^^^
  File "/home/rashid/.cache/pypoetry/virtualenvs/cropgnosis-p5HYragw-py3.11/lib/python3.11/site-packages/django/utils/decorators.py", line 48, in _wrapper
    return bound_method(*args, **kwargs)
           ^^^^^^^^^^^^^^^^^^^^^^^^^^^^^
  File "/home/rashid/.cache/pypoetry/virtualenvs/cropgnosis-p5HYragw-py3.11/lib/python3.11/site-packages/django/utils/decorators.py", line 188, in _view_wrapper
    result = _process_exception(request, e)
             ^^^^^^^^^^^^^^^^^^^^^^^^^^^^^^
  File "/home/rashid/.cache/pypoetry/virtualenvs/cropgnosis-p5HYragw-py3.11/lib/python3.11/site-packages/django/utils/decorators.py", line 186, in _view_wrapper
    response = view_func(request, *args, **kwargs)
               ^^^^^^^^^^^^^^^^^^^^^^^^^^^^^^^^^^^
  File "/home/rashid/.cache/pypoetry/virtualenvs/cropgnosis-p5HYragw-py3.11/lib/python3.11/site-packages/django/contrib/admin/options.py", line 2123, in changelist_view
    "selection_note": _("0 of %(cnt)s selected") % {"cnt": len(cl.result_list)},
                                                           ^^^^^^^^^^^^^^^^^^^
  File "/home/rashid/.cache/pypoetry/virtualenvs/cropgnosis-p5HYragw-py3.11/lib/python3.11/site-packages/django/db/models/query.py", line 382, in __len__
    self._fetch_all()
  File "/home/rashid/.cache/pypoetry/virtualenvs/cropgnosis-p5HYragw-py3.11/lib/python3.11/site-packages/django/db/models/query.py", line 1928, in _fetch_all
    self._result_cache = list(self._iterable_class(self))
                         ^^^^^^^^^^^^^^^^^^^^^^^^^^^^^^^^
  File "/home/rashid/.cache/pypoetry/virtualenvs/cropgnosis-p5HYragw-py3.11/lib/python3.11/site-packages/django/db/models/query.py", line 91, in __iter__
    results = compiler.execute_sql(
              ^^^^^^^^^^^^^^^^^^^^^
  File "/home/rashid/.cache/pypoetry/virtualenvs/cropgnosis-p5HYragw-py3.11/lib/python3.11/site-packages/django/db/models/sql/compiler.py", line 1562, in execute_sql
    cursor.execute(sql, params)
  File "/home/rashid/.cache/pypoetry/virtualenvs/cropgnosis-p5HYragw-py3.11/lib/python3.11/site-packages/django/db/backends/utils.py", line 122, in execute
    return super().execute(sql, params)
           ^^^^^^^^^^^^^^^^^^^^^^^^^^^^
  File "/home/rashid/.cache/pypoetry/virtualenvs/cropgnosis-p5HYragw-py3.11/lib/python3.11/site-packages/django/db/backends/utils.py", line 79, in execute
    return self._execute_with_wrappers(
           ^^^^^^^^^^^^^^^^^^^^^^^^^^^^
  File "/home/rashid/.cache/pypoetry/virtualenvs/cropgnosis-p5HYragw-py3.11/lib/python3.11/site-packages/django/db/backends/utils.py", line 92, in _execute_with_wrappers
    return executor(sql, params, many, context)
           ^^^^^^^^^^^^^^^^^^^^^^^^^^^^^^^^^^^^
  File "/home/rashid/.cache/pypoetry/virtualenvs/cropgnosis-p5HYragw-py3.11/lib/python3.11/site-packages/django/db/backends/utils.py", line 100, in _execute
    with self.db.wrap_database_errors:
  File "/home/rashid/.cache/pypoetry/virtualenvs/cropgnosis-p5HYragw-py3.11/lib/python3.11/site-packages/django/db/utils.py", line 91, in __exit__
    raise dj_exc_value.with_traceback(traceback) from exc_value
  File "/home/rashid/.cache/pypoetry/virtualenvs/cropgnosis-p5HYragw-py3.11/lib/python3.11/site-packages/django/db/backends/utils.py", line 105, in _execute
    return self.cursor.execute(sql, params)
           ^^^^^^^^^^^^^^^^^^^^^^^^^^^^^^^^
django.db.utils.ProgrammingError: operator does not exist: bigint = uuid
LINE 1: ...zation_mentorsubscriptions"."mentor_base_plan_id" = "authori...
                                                             ^
HINT:  No operator matches the given name and argument types. You might need to add explicit type casts.

[31/Mar/2024 15:43:07] ERROR [django.request:241] Internal Server Error: /admin/authorization/mentorsubscriptions/
Traceback (most recent call last):
  File "/home/rashid/.cache/pypoetry/virtualenvs/cropgnosis-p5HYragw-py3.11/lib/python3.11/site-packages/django/db/backends/utils.py", line 105, in _execute
    return self.cursor.execute(sql, params)
           ^^^^^^^^^^^^^^^^^^^^^^^^^^^^^^^^
psycopg2.errors.UndefinedFunction: operator does not exist: bigint = uuid
LINE 1: ...zation_mentorsubscriptions"."mentor_base_plan_id" = "authori...
                                                             ^
HINT:  No operator matches the given name and argument types. You might need to add explicit type casts.


The above exception was the direct cause of the following exception:

Traceback (most recent call last):
  File "/home/rashid/.cache/pypoetry/virtualenvs/cropgnosis-p5HYragw-py3.11/lib/python3.11/site-packages/django/core/handlers/exception.py", line 55, in inner
    response = get_response(request)
               ^^^^^^^^^^^^^^^^^^^^^
  File "/home/rashid/.cache/pypoetry/virtualenvs/cropgnosis-p5HYragw-py3.11/lib/python3.11/site-packages/django/core/handlers/base.py", line 197, in _get_response
    response = wrapped_callback(request, *callback_args, **callback_kwargs)
               ^^^^^^^^^^^^^^^^^^^^^^^^^^^^^^^^^^^^^^^^^^^^^^^^^^^^^^^^^^^^
  File "/home/rashid/.cache/pypoetry/virtualenvs/cropgnosis-p5HYragw-py3.11/lib/python3.11/site-packages/django/contrib/admin/options.py", line 715, in wrapper
    return self.admin_site.admin_view(view)(*args, **kwargs)
           ^^^^^^^^^^^^^^^^^^^^^^^^^^^^^^^^^^^^^^^^^^^^^^^^^
  File "/home/rashid/.cache/pypoetry/virtualenvs/cropgnosis-p5HYragw-py3.11/lib/python3.11/site-packages/django/utils/decorators.py", line 188, in _view_wrapper
    result = _process_exception(request, e)
             ^^^^^^^^^^^^^^^^^^^^^^^^^^^^^^
  File "/home/rashid/.cache/pypoetry/virtualenvs/cropgnosis-p5HYragw-py3.11/lib/python3.11/site-packages/django/utils/decorators.py", line 186, in _view_wrapper
    response = view_func(request, *args, **kwargs)
               ^^^^^^^^^^^^^^^^^^^^^^^^^^^^^^^^^^^
  File "/home/rashid/.cache/pypoetry/virtualenvs/cropgnosis-p5HYragw-py3.11/lib/python3.11/site-packages/django/views/decorators/cache.py", line 80, in _view_wrapper
    response = view_func(request, *args, **kwargs)
               ^^^^^^^^^^^^^^^^^^^^^^^^^^^^^^^^^^^
  File "/home/rashid/.cache/pypoetry/virtualenvs/cropgnosis-p5HYragw-py3.11/lib/python3.11/site-packages/django/contrib/admin/sites.py", line 240, in inner
    return view(request, *args, **kwargs)
           ^^^^^^^^^^^^^^^^^^^^^^^^^^^^^^
  File "/home/rashid/.cache/pypoetry/virtualenvs/cropgnosis-p5HYragw-py3.11/lib/python3.11/site-packages/django/utils/decorators.py", line 48, in _wrapper
    return bound_method(*args, **kwargs)
           ^^^^^^^^^^^^^^^^^^^^^^^^^^^^^
  File "/home/rashid/.cache/pypoetry/virtualenvs/cropgnosis-p5HYragw-py3.11/lib/python3.11/site-packages/django/utils/decorators.py", line 188, in _view_wrapper
    result = _process_exception(request, e)
             ^^^^^^^^^^^^^^^^^^^^^^^^^^^^^^
  File "/home/rashid/.cache/pypoetry/virtualenvs/cropgnosis-p5HYragw-py3.11/lib/python3.11/site-packages/django/utils/decorators.py", line 186, in _view_wrapper
    response = view_func(request, *args, **kwargs)
               ^^^^^^^^^^^^^^^^^^^^^^^^^^^^^^^^^^^
  File "/home/rashid/.cache/pypoetry/virtualenvs/cropgnosis-p5HYragw-py3.11/lib/python3.11/site-packages/django/contrib/admin/options.py", line 2123, in changelist_view
    "selection_note": _("0 of %(cnt)s selected") % {"cnt": len(cl.result_list)},
                                                           ^^^^^^^^^^^^^^^^^^^
  File "/home/rashid/.cache/pypoetry/virtualenvs/cropgnosis-p5HYragw-py3.11/lib/python3.11/site-packages/django/db/models/query.py", line 382, in __len__
    self._fetch_all()
  File "/home/rashid/.cache/pypoetry/virtualenvs/cropgnosis-p5HYragw-py3.11/lib/python3.11/site-packages/django/db/models/query.py", line 1928, in _fetch_all
    self._result_cache = list(self._iterable_class(self))
                         ^^^^^^^^^^^^^^^^^^^^^^^^^^^^^^^^
  File "/home/rashid/.cache/pypoetry/virtualenvs/cropgnosis-p5HYragw-py3.11/lib/python3.11/site-packages/django/db/models/query.py", line 91, in __iter__
    results = compiler.execute_sql(
              ^^^^^^^^^^^^^^^^^^^^^
  File "/home/rashid/.cache/pypoetry/virtualenvs/cropgnosis-p5HYragw-py3.11/lib/python3.11/site-packages/django/db/models/sql/compiler.py", line 1562, in execute_sql
    cursor.execute(sql, params)
  File "/home/rashid/.cache/pypoetry/virtualenvs/cropgnosis-p5HYragw-py3.11/lib/python3.11/site-packages/django/db/backends/utils.py", line 122, in execute
    return super().execute(sql, params)
           ^^^^^^^^^^^^^^^^^^^^^^^^^^^^
  File "/home/rashid/.cache/pypoetry/virtualenvs/cropgnosis-p5HYragw-py3.11/lib/python3.11/site-packages/django/db/backends/utils.py", line 79, in execute
    return self._execute_with_wrappers(
           ^^^^^^^^^^^^^^^^^^^^^^^^^^^^
  File "/home/rashid/.cache/pypoetry/virtualenvs/cropgnosis-p5HYragw-py3.11/lib/python3.11/site-packages/django/db/backends/utils.py", line 92, in _execute_with_wrappers
    return executor(sql, params, many, context)
           ^^^^^^^^^^^^^^^^^^^^^^^^^^^^^^^^^^^^
  File "/home/rashid/.cache/pypoetry/virtualenvs/cropgnosis-p5HYragw-py3.11/lib/python3.11/site-packages/django/db/backends/utils.py", line 100, in _execute
    with self.db.wrap_database_errors:
  File "/home/rashid/.cache/pypoetry/virtualenvs/cropgnosis-p5HYragw-py3.11/lib/python3.11/site-packages/django/db/utils.py", line 91, in __exit__
    raise dj_exc_value.with_traceback(traceback) from exc_value
  File "/home/rashid/.cache/pypoetry/virtualenvs/cropgnosis-p5HYragw-py3.11/lib/python3.11/site-packages/django/db/backends/utils.py", line 105, in _execute
    return self.cursor.execute(sql, params)
           ^^^^^^^^^^^^^^^^^^^^^^^^^^^^^^^^
django.db.utils.ProgrammingError: operator does not exist: bigint = uuid
LINE 1: ...zation_mentorsubscriptions"."mentor_base_plan_id" = "authori...
                                                             ^
HINT:  No operator matches the given name and argument types. You might need to add explicit type casts.

[31/Mar/2024 15:44:11] ERROR [django.request:241] Internal Server Error: /admin/authorization/mentorsubscriptions/
Traceback (most recent call last):
  File "/home/rashid/.cache/pypoetry/virtualenvs/cropgnosis-p5HYragw-py3.11/lib/python3.11/site-packages/django/db/backends/utils.py", line 105, in _execute
    return self.cursor.execute(sql, params)
           ^^^^^^^^^^^^^^^^^^^^^^^^^^^^^^^^
psycopg2.errors.UndefinedFunction: operator does not exist: bigint = uuid
LINE 1: ...zation_mentorsubscriptions"."mentor_base_plan_id" = "authori...
                                                             ^
HINT:  No operator matches the given name and argument types. You might need to add explicit type casts.


The above exception was the direct cause of the following exception:

Traceback (most recent call last):
  File "/home/rashid/.cache/pypoetry/virtualenvs/cropgnosis-p5HYragw-py3.11/lib/python3.11/site-packages/django/core/handlers/exception.py", line 55, in inner
    response = get_response(request)
               ^^^^^^^^^^^^^^^^^^^^^
  File "/home/rashid/.cache/pypoetry/virtualenvs/cropgnosis-p5HYragw-py3.11/lib/python3.11/site-packages/django/core/handlers/base.py", line 197, in _get_response
    response = wrapped_callback(request, *callback_args, **callback_kwargs)
               ^^^^^^^^^^^^^^^^^^^^^^^^^^^^^^^^^^^^^^^^^^^^^^^^^^^^^^^^^^^^
  File "/home/rashid/.cache/pypoetry/virtualenvs/cropgnosis-p5HYragw-py3.11/lib/python3.11/site-packages/django/contrib/admin/options.py", line 715, in wrapper
    return self.admin_site.admin_view(view)(*args, **kwargs)
           ^^^^^^^^^^^^^^^^^^^^^^^^^^^^^^^^^^^^^^^^^^^^^^^^^
  File "/home/rashid/.cache/pypoetry/virtualenvs/cropgnosis-p5HYragw-py3.11/lib/python3.11/site-packages/django/utils/decorators.py", line 188, in _view_wrapper
    result = _process_exception(request, e)
             ^^^^^^^^^^^^^^^^^^^^^^^^^^^^^^
  File "/home/rashid/.cache/pypoetry/virtualenvs/cropgnosis-p5HYragw-py3.11/lib/python3.11/site-packages/django/utils/decorators.py", line 186, in _view_wrapper
    response = view_func(request, *args, **kwargs)
               ^^^^^^^^^^^^^^^^^^^^^^^^^^^^^^^^^^^
  File "/home/rashid/.cache/pypoetry/virtualenvs/cropgnosis-p5HYragw-py3.11/lib/python3.11/site-packages/django/views/decorators/cache.py", line 80, in _view_wrapper
    response = view_func(request, *args, **kwargs)
               ^^^^^^^^^^^^^^^^^^^^^^^^^^^^^^^^^^^
  File "/home/rashid/.cache/pypoetry/virtualenvs/cropgnosis-p5HYragw-py3.11/lib/python3.11/site-packages/django/contrib/admin/sites.py", line 240, in inner
    return view(request, *args, **kwargs)
           ^^^^^^^^^^^^^^^^^^^^^^^^^^^^^^
  File "/home/rashid/.cache/pypoetry/virtualenvs/cropgnosis-p5HYragw-py3.11/lib/python3.11/site-packages/django/utils/decorators.py", line 48, in _wrapper
    return bound_method(*args, **kwargs)
           ^^^^^^^^^^^^^^^^^^^^^^^^^^^^^
  File "/home/rashid/.cache/pypoetry/virtualenvs/cropgnosis-p5HYragw-py3.11/lib/python3.11/site-packages/django/utils/decorators.py", line 188, in _view_wrapper
    result = _process_exception(request, e)
             ^^^^^^^^^^^^^^^^^^^^^^^^^^^^^^
  File "/home/rashid/.cache/pypoetry/virtualenvs/cropgnosis-p5HYragw-py3.11/lib/python3.11/site-packages/django/utils/decorators.py", line 186, in _view_wrapper
    response = view_func(request, *args, **kwargs)
               ^^^^^^^^^^^^^^^^^^^^^^^^^^^^^^^^^^^
  File "/home/rashid/.cache/pypoetry/virtualenvs/cropgnosis-p5HYragw-py3.11/lib/python3.11/site-packages/django/contrib/admin/options.py", line 2123, in changelist_view
    "selection_note": _("0 of %(cnt)s selected") % {"cnt": len(cl.result_list)},
                                                           ^^^^^^^^^^^^^^^^^^^
  File "/home/rashid/.cache/pypoetry/virtualenvs/cropgnosis-p5HYragw-py3.11/lib/python3.11/site-packages/django/db/models/query.py", line 382, in __len__
    self._fetch_all()
  File "/home/rashid/.cache/pypoetry/virtualenvs/cropgnosis-p5HYragw-py3.11/lib/python3.11/site-packages/django/db/models/query.py", line 1928, in _fetch_all
    self._result_cache = list(self._iterable_class(self))
                         ^^^^^^^^^^^^^^^^^^^^^^^^^^^^^^^^
  File "/home/rashid/.cache/pypoetry/virtualenvs/cropgnosis-p5HYragw-py3.11/lib/python3.11/site-packages/django/db/models/query.py", line 91, in __iter__
    results = compiler.execute_sql(
              ^^^^^^^^^^^^^^^^^^^^^
  File "/home/rashid/.cache/pypoetry/virtualenvs/cropgnosis-p5HYragw-py3.11/lib/python3.11/site-packages/django/db/models/sql/compiler.py", line 1562, in execute_sql
    cursor.execute(sql, params)
  File "/home/rashid/.cache/pypoetry/virtualenvs/cropgnosis-p5HYragw-py3.11/lib/python3.11/site-packages/django/db/backends/utils.py", line 122, in execute
    return super().execute(sql, params)
           ^^^^^^^^^^^^^^^^^^^^^^^^^^^^
  File "/home/rashid/.cache/pypoetry/virtualenvs/cropgnosis-p5HYragw-py3.11/lib/python3.11/site-packages/django/db/backends/utils.py", line 79, in execute
    return self._execute_with_wrappers(
           ^^^^^^^^^^^^^^^^^^^^^^^^^^^^
  File "/home/rashid/.cache/pypoetry/virtualenvs/cropgnosis-p5HYragw-py3.11/lib/python3.11/site-packages/django/db/backends/utils.py", line 92, in _execute_with_wrappers
    return executor(sql, params, many, context)
           ^^^^^^^^^^^^^^^^^^^^^^^^^^^^^^^^^^^^
  File "/home/rashid/.cache/pypoetry/virtualenvs/cropgnosis-p5HYragw-py3.11/lib/python3.11/site-packages/django/db/backends/utils.py", line 100, in _execute
    with self.db.wrap_database_errors:
  File "/home/rashid/.cache/pypoetry/virtualenvs/cropgnosis-p5HYragw-py3.11/lib/python3.11/site-packages/django/db/utils.py", line 91, in __exit__
    raise dj_exc_value.with_traceback(traceback) from exc_value
  File "/home/rashid/.cache/pypoetry/virtualenvs/cropgnosis-p5HYragw-py3.11/lib/python3.11/site-packages/django/db/backends/utils.py", line 105, in _execute
    return self.cursor.execute(sql, params)
           ^^^^^^^^^^^^^^^^^^^^^^^^^^^^^^^^
django.db.utils.ProgrammingError: operator does not exist: bigint = uuid
LINE 1: ...zation_mentorsubscriptions"."mentor_base_plan_id" = "authori...
                                                             ^
HINT:  No operator matches the given name and argument types. You might need to add explicit type casts.

[01/Apr/2024 02:42:02] WARNING [django.request:241] Not Found: /
[01/Apr/2024 02:42:59] WARNING [django.request:241] Forbidden: /api/auth/mentor/login
[21/Apr/2024 11:14:14] WARNING [django.request:241] Not Found: /
[21/Apr/2024 11:17:13] WARNING [django.request:241] Bad Request: /api/auth/customer/registration
[21/Apr/2024 11:17:17] WARNING [django.request:241] Bad Request: /api/auth/customer/registration
[21/Apr/2024 11:19:35] WARNING [django.request:241] Unauthorized: /api/auth/customer/address
[21/Apr/2024 11:19:51] WARNING [django.request:241] Unauthorized: /api/auth/customer/address
[21/Apr/2024 11:21:27] WARNING [django.request:241] Unauthorized: /api/auth/customer/address
[21/Apr/2024 11:21:46] WARNING [django.request:241] Unauthorized: /api/auth/customer/address
[21/Apr/2024 11:25:12] WARNING [django.request:241] Forbidden: /api/auth/mentor/login
[21/Apr/2024 11:26:48] WARNING [django.request:241] Forbidden: /api/auth/mentor/login
[21/Apr/2024 11:30:47] WARNING [django.request:241] Unauthorized: /api/auth/mentor/update-account
[21/Apr/2024 11:33:44] WARNING [django.request:241] Not Found: /api/auth/mentor/update-address
[21/Apr/2024 11:35:11] WARNING [django.request:241] Unauthorized: /api/auth/mentor/address
[21/Apr/2024 11:36:38] WARNING [django.request:241] Not Found: /api/auth/mentor/add-basementorplan
[21/Apr/2024 11:39:53] WARNING [django.request:241] Unauthorized: /api/common/base-plans
[23/Apr/2024 03:57:41] WARNING [django.request:241] Not Found: /
[23/Apr/2024 03:57:42] WARNING [django.request:241] Not Found: /favicon.ico
[23/Apr/2024 04:09:18] WARNING [django.request:241] Not Found: /
[23/Apr/2024 04:09:26] WARNING [django.request:241] Not Found: /api/subscription/style.css
[23/Apr/2024 04:09:36] WARNING [django.request:241] Not Found: /api/subscription/style.css
[23/Apr/2024 04:09:39] WARNING [django.request:241] Bad Request: /api/subscription/subscription-check-out
[23/Apr/2024 04:09:51] WARNING [django.request:241] Not Found: /api/subscription/style.css
[23/Apr/2024 04:13:19] WARNING [django.request:241] Not Found: /api/subscription/style.css
[23/Apr/2024 04:13:22] ERROR [django.request:241] Internal Server Error: /api/subscription/subscription-check-out
Traceback (most recent call last):
  File "/home/rashid/.cache/pypoetry/virtualenvs/cropgnosis-p5HYragw-py3.11/lib/python3.11/site-packages/django/db/backends/utils.py", line 105, in _execute
    return self.cursor.execute(sql, params)
           ^^^^^^^^^^^^^^^^^^^^^^^^^^^^^^^^
psycopg2.errors.StringDataRightTruncation: value too long for type character varying(50)


The above exception was the direct cause of the following exception:

Traceback (most recent call last):
  File "/home/rashid/.cache/pypoetry/virtualenvs/cropgnosis-p5HYragw-py3.11/lib/python3.11/site-packages/django/core/handlers/exception.py", line 55, in inner
    response = get_response(request)
               ^^^^^^^^^^^^^^^^^^^^^
  File "/home/rashid/.cache/pypoetry/virtualenvs/cropgnosis-p5HYragw-py3.11/lib/python3.11/site-packages/django/core/handlers/base.py", line 197, in _get_response
    response = wrapped_callback(request, *callback_args, **callback_kwargs)
               ^^^^^^^^^^^^^^^^^^^^^^^^^^^^^^^^^^^^^^^^^^^^^^^^^^^^^^^^^^^^
  File "/home/rashid/.cache/pypoetry/virtualenvs/cropgnosis-p5HYragw-py3.11/lib/python3.11/site-packages/django/views/decorators/csrf.py", line 65, in _view_wrapper
    return view_func(request, *args, **kwargs)
           ^^^^^^^^^^^^^^^^^^^^^^^^^^^^^^^^^^^
  File "/home/rashid/.cache/pypoetry/virtualenvs/cropgnosis-p5HYragw-py3.11/lib/python3.11/site-packages/django/views/generic/base.py", line 104, in view
    return self.dispatch(request, *args, **kwargs)
           ^^^^^^^^^^^^^^^^^^^^^^^^^^^^^^^^^^^^^^^
  File "/home/rashid/.cache/pypoetry/virtualenvs/cropgnosis-p5HYragw-py3.11/lib/python3.11/site-packages/rest_framework/views.py", line 509, in dispatch
    response = self.handle_exception(exc)
               ^^^^^^^^^^^^^^^^^^^^^^^^^^
  File "/home/rashid/.cache/pypoetry/virtualenvs/cropgnosis-p5HYragw-py3.11/lib/python3.11/site-packages/rest_framework/views.py", line 469, in handle_exception
    self.raise_uncaught_exception(exc)
  File "/home/rashid/.cache/pypoetry/virtualenvs/cropgnosis-p5HYragw-py3.11/lib/python3.11/site-packages/rest_framework/views.py", line 480, in raise_uncaught_exception
    raise exc
  File "/home/rashid/.cache/pypoetry/virtualenvs/cropgnosis-p5HYragw-py3.11/lib/python3.11/site-packages/rest_framework/views.py", line 506, in dispatch
    response = handler(request, *args, **kwargs)
               ^^^^^^^^^^^^^^^^^^^^^^^^^^^^^^^^^
  File "/home/rashid/Projects/CropGnisis/CropGnosis/apps/subscription/views/customer_views.py", line 60, in post
    transaction.save()
  File "/home/rashid/Projects/CropGnisis/CropGnosis/apps/subscription/models.py", line 190, in save
    super(PaymentTransactions,self).save(*args, **kwargs)
  File "/home/rashid/.cache/pypoetry/virtualenvs/cropgnosis-p5HYragw-py3.11/lib/python3.11/site-packages/django/db/models/base.py", line 822, in save
    self.save_base(
  File "/home/rashid/.cache/pypoetry/virtualenvs/cropgnosis-p5HYragw-py3.11/lib/python3.11/site-packages/django/db/models/base.py", line 909, in save_base
    updated = self._save_table(
              ^^^^^^^^^^^^^^^^^
  File "/home/rashid/.cache/pypoetry/virtualenvs/cropgnosis-p5HYragw-py3.11/lib/python3.11/site-packages/django/db/models/base.py", line 1036, in _save_table
    updated = self._do_update(
              ^^^^^^^^^^^^^^^^
  File "/home/rashid/.cache/pypoetry/virtualenvs/cropgnosis-p5HYragw-py3.11/lib/python3.11/site-packages/django/db/models/base.py", line 1101, in _do_update
    return filtered._update(values) > 0
           ^^^^^^^^^^^^^^^^^^^^^^^^
  File "/home/rashid/.cache/pypoetry/virtualenvs/cropgnosis-p5HYragw-py3.11/lib/python3.11/site-packages/django/db/models/query.py", line 1278, in _update
    return query.get_compiler(self.db).execute_sql(CURSOR)
           ^^^^^^^^^^^^^^^^^^^^^^^^^^^^^^^^^^^^^^^^^^^^^^^
  File "/home/rashid/.cache/pypoetry/virtualenvs/cropgnosis-p5HYragw-py3.11/lib/python3.11/site-packages/django/db/models/sql/compiler.py", line 1990, in execute_sql
    cursor = super().execute_sql(result_type)
             ^^^^^^^^^^^^^^^^^^^^^^^^^^^^^^^^
  File "/home/rashid/.cache/pypoetry/virtualenvs/cropgnosis-p5HYragw-py3.11/lib/python3.11/site-packages/django/db/models/sql/compiler.py", line 1562, in execute_sql
    cursor.execute(sql, params)
  File "/home/rashid/.cache/pypoetry/virtualenvs/cropgnosis-p5HYragw-py3.11/lib/python3.11/site-packages/django/db/backends/utils.py", line 122, in execute
    return super().execute(sql, params)
           ^^^^^^^^^^^^^^^^^^^^^^^^^^^^
  File "/home/rashid/.cache/pypoetry/virtualenvs/cropgnosis-p5HYragw-py3.11/lib/python3.11/site-packages/django/db/backends/utils.py", line 79, in execute
    return self._execute_with_wrappers(
           ^^^^^^^^^^^^^^^^^^^^^^^^^^^^
  File "/home/rashid/.cache/pypoetry/virtualenvs/cropgnosis-p5HYragw-py3.11/lib/python3.11/site-packages/django/db/backends/utils.py", line 92, in _execute_with_wrappers
    return executor(sql, params, many, context)
           ^^^^^^^^^^^^^^^^^^^^^^^^^^^^^^^^^^^^
  File "/home/rashid/.cache/pypoetry/virtualenvs/cropgnosis-p5HYragw-py3.11/lib/python3.11/site-packages/django/db/backends/utils.py", line 100, in _execute
    with self.db.wrap_database_errors:
  File "/home/rashid/.cache/pypoetry/virtualenvs/cropgnosis-p5HYragw-py3.11/lib/python3.11/site-packages/django/db/utils.py", line 91, in __exit__
    raise dj_exc_value.with_traceback(traceback) from exc_value
  File "/home/rashid/.cache/pypoetry/virtualenvs/cropgnosis-p5HYragw-py3.11/lib/python3.11/site-packages/django/db/backends/utils.py", line 105, in _execute
    return self.cursor.execute(sql, params)
           ^^^^^^^^^^^^^^^^^^^^^^^^^^^^^^^^
django.db.utils.DataError: value too long for type character varying(50)

[23/Apr/2024 04:17:53] WARNING [django.request:241] Not Found: /api/subscription/style.css
[23/Apr/2024 04:20:00] WARNING [django.request:241] Not Found: /api/subscription/style.css
[23/Apr/2024 04:21:03] WARNING [django.request:241] Not Found: /api/subscription/style.css
[23/Apr/2024 04:23:48] ERROR [django.request:241] Internal Server Error: /api/subscription/payment-success-callback
[23/Apr/2024 04:27:23] ERROR [django.request:241] Internal Server Error: /api/subscription/payment-success-callback
[23/Apr/2024 04:28:07] ERROR [django.request:241] Internal Server Error: /api/subscription/payment-success-callback
[23/Apr/2024 04:28:59] ERROR [django.request:241] Internal Server Error: /api/subscription/payment-success-callback
[23/Apr/2024 04:30:04] ERROR [django.request:241] Internal Server Error: /api/subscription/payment-success-callback
[23/Apr/2024 04:30:10] ERROR [django.request:241] Internal Server Error: /api/subscription/payment-success-callback
[23/Apr/2024 04:41:44] ERROR [django.request:241] Internal Server Error: /api/subscription/payment-success-callback
[23/Apr/2024 04:42:24] ERROR [django.request:241] Internal Server Error: /api/subscription/payment-success-callback
[23/Apr/2024 04:51:43] WARNING [django.request:241] Not Found: /api/subscription/style.css
[23/Apr/2024 05:59:19] WARNING [django.request:241] Not Found: /
[27/Apr/2024 08:52:20] WARNING [django.request:241] Not Found: /
[27/Apr/2024 08:52:21] WARNING [django.request:241] Not Found: /favicon.ico
[27/Apr/2024 08:55:14] WARNING [django.request:241] Unauthorized: /api/subscription/subscription-check-out
[27/Apr/2024 10:41:30] ERROR [django.request:241] Internal Server Error: /api/subscription/addon-checkout
Traceback (most recent call last):
  File "/home/rashid/.cache/pypoetry/virtualenvs/cropgnosis-p5HYragw-py3.11/lib/python3.11/site-packages/django/db/backends/utils.py", line 105, in _execute
    return self.cursor.execute(sql, params)
           ^^^^^^^^^^^^^^^^^^^^^^^^^^^^^^^^
psycopg2.errors.UndefinedColumn: column subscription_essentialfeatures.periodicity does not exist
LINE 1: ...", "subscription_essentialfeatures"."updated_at", "subscript...
                                                             ^


The above exception was the direct cause of the following exception:

Traceback (most recent call last):
  File "/home/rashid/.cache/pypoetry/virtualenvs/cropgnosis-p5HYragw-py3.11/lib/python3.11/site-packages/django/core/handlers/exception.py", line 55, in inner
    response = get_response(request)
               ^^^^^^^^^^^^^^^^^^^^^
  File "/home/rashid/.cache/pypoetry/virtualenvs/cropgnosis-p5HYragw-py3.11/lib/python3.11/site-packages/django/core/handlers/base.py", line 197, in _get_response
    response = wrapped_callback(request, *callback_args, **callback_kwargs)
               ^^^^^^^^^^^^^^^^^^^^^^^^^^^^^^^^^^^^^^^^^^^^^^^^^^^^^^^^^^^^
  File "/home/rashid/.cache/pypoetry/virtualenvs/cropgnosis-p5HYragw-py3.11/lib/python3.11/site-packages/django/views/decorators/csrf.py", line 65, in _view_wrapper
    return view_func(request, *args, **kwargs)
           ^^^^^^^^^^^^^^^^^^^^^^^^^^^^^^^^^^^
  File "/home/rashid/.cache/pypoetry/virtualenvs/cropgnosis-p5HYragw-py3.11/lib/python3.11/site-packages/django/views/generic/base.py", line 104, in view
    return self.dispatch(request, *args, **kwargs)
           ^^^^^^^^^^^^^^^^^^^^^^^^^^^^^^^^^^^^^^^
  File "/home/rashid/.cache/pypoetry/virtualenvs/cropgnosis-p5HYragw-py3.11/lib/python3.11/site-packages/rest_framework/views.py", line 509, in dispatch
    response = self.handle_exception(exc)
               ^^^^^^^^^^^^^^^^^^^^^^^^^^
  File "/home/rashid/.cache/pypoetry/virtualenvs/cropgnosis-p5HYragw-py3.11/lib/python3.11/site-packages/rest_framework/views.py", line 469, in handle_exception
    self.raise_uncaught_exception(exc)
  File "/home/rashid/.cache/pypoetry/virtualenvs/cropgnosis-p5HYragw-py3.11/lib/python3.11/site-packages/rest_framework/views.py", line 480, in raise_uncaught_exception
    raise exc
  File "/home/rashid/.cache/pypoetry/virtualenvs/cropgnosis-p5HYragw-py3.11/lib/python3.11/site-packages/rest_framework/views.py", line 506, in dispatch
    response = handler(request, *args, **kwargs)
               ^^^^^^^^^^^^^^^^^^^^^^^^^^^^^^^^^
  File "/home/rashid/Projects/CropGnisis/CropGnosis/apps/subscription/views/customer_views.py", line 97, in post
    addon_plan_obj = EssentialFeatures.objects.filter(pk = addon_plan_uuid).last()
                     ^^^^^^^^^^^^^^^^^^^^^^^^^^^^^^^^^^^^^^^^^^^^^^^^^^^^^^^^^^^^^
  File "/home/rashid/.cache/pypoetry/virtualenvs/cropgnosis-p5HYragw-py3.11/lib/python3.11/site-packages/django/db/models/query.py", line 1110, in last
    for obj in queryset[:1]:
  File "/home/rashid/.cache/pypoetry/virtualenvs/cropgnosis-p5HYragw-py3.11/lib/python3.11/site-packages/django/db/models/query.py", line 400, in __iter__
    self._fetch_all()
  File "/home/rashid/.cache/pypoetry/virtualenvs/cropgnosis-p5HYragw-py3.11/lib/python3.11/site-packages/django/db/models/query.py", line 1928, in _fetch_all
    self._result_cache = list(self._iterable_class(self))
                         ^^^^^^^^^^^^^^^^^^^^^^^^^^^^^^^^
  File "/home/rashid/.cache/pypoetry/virtualenvs/cropgnosis-p5HYragw-py3.11/lib/python3.11/site-packages/django/db/models/query.py", line 91, in __iter__
    results = compiler.execute_sql(
              ^^^^^^^^^^^^^^^^^^^^^
  File "/home/rashid/.cache/pypoetry/virtualenvs/cropgnosis-p5HYragw-py3.11/lib/python3.11/site-packages/django/db/models/sql/compiler.py", line 1562, in execute_sql
    cursor.execute(sql, params)
  File "/home/rashid/.cache/pypoetry/virtualenvs/cropgnosis-p5HYragw-py3.11/lib/python3.11/site-packages/django/db/backends/utils.py", line 122, in execute
    return super().execute(sql, params)
           ^^^^^^^^^^^^^^^^^^^^^^^^^^^^
  File "/home/rashid/.cache/pypoetry/virtualenvs/cropgnosis-p5HYragw-py3.11/lib/python3.11/site-packages/django/db/backends/utils.py", line 79, in execute
    return self._execute_with_wrappers(
           ^^^^^^^^^^^^^^^^^^^^^^^^^^^^
  File "/home/rashid/.cache/pypoetry/virtualenvs/cropgnosis-p5HYragw-py3.11/lib/python3.11/site-packages/django/db/backends/utils.py", line 92, in _execute_with_wrappers
    return executor(sql, params, many, context)
           ^^^^^^^^^^^^^^^^^^^^^^^^^^^^^^^^^^^^
  File "/home/rashid/.cache/pypoetry/virtualenvs/cropgnosis-p5HYragw-py3.11/lib/python3.11/site-packages/django/db/backends/utils.py", line 100, in _execute
    with self.db.wrap_database_errors:
  File "/home/rashid/.cache/pypoetry/virtualenvs/cropgnosis-p5HYragw-py3.11/lib/python3.11/site-packages/django/db/utils.py", line 91, in __exit__
    raise dj_exc_value.with_traceback(traceback) from exc_value
  File "/home/rashid/.cache/pypoetry/virtualenvs/cropgnosis-p5HYragw-py3.11/lib/python3.11/site-packages/django/db/backends/utils.py", line 105, in _execute
    return self.cursor.execute(sql, params)
           ^^^^^^^^^^^^^^^^^^^^^^^^^^^^^^^^
django.db.utils.ProgrammingError: column subscription_essentialfeatures.periodicity does not exist
LINE 1: ...", "subscription_essentialfeatures"."updated_at", "subscript...
                                                             ^

[27/Apr/2024 10:44:45] WARNING [django.request:241] Not Found: /
[27/Apr/2024 10:46:44] WARNING [django.request:241] Not Found: /subscription/addon-checkout
[27/Apr/2024 10:46:51] WARNING [django.request:241] Not Found: /api/subscription/style.css
[27/Apr/2024 11:41:47] WARNING [django.request:241] Unauthorized: /api/subscription/mentor/add-basementorplan
[27/Apr/2024 11:52:14] WARNING [django.request:241] Unauthorized: /api/subscription/mentor/add-basementorplan
[27/Apr/2024 11:52:55] WARNING [django.request:241] Unauthorized: /api/subscription/mentor/add-basementorplan
[27/Apr/2024 11:53:06] WARNING [django.request:241] Unauthorized: /api/subscription/mentor/add-basementorplan
[27/Apr/2024 12:04:01] ERROR [django.request:241] Internal Server Error: /api/common/mentor-plans
Traceback (most recent call last):
  File "/home/rashid/.cache/pypoetry/virtualenvs/cropgnosis-p5HYragw-py3.11/lib/python3.11/site-packages/django/core/handlers/exception.py", line 55, in inner
    response = get_response(request)
               ^^^^^^^^^^^^^^^^^^^^^
  File "/home/rashid/.cache/pypoetry/virtualenvs/cropgnosis-p5HYragw-py3.11/lib/python3.11/site-packages/django/core/handlers/base.py", line 197, in _get_response
    response = wrapped_callback(request, *callback_args, **callback_kwargs)
               ^^^^^^^^^^^^^^^^^^^^^^^^^^^^^^^^^^^^^^^^^^^^^^^^^^^^^^^^^^^^
  File "/home/rashid/.cache/pypoetry/virtualenvs/cropgnosis-p5HYragw-py3.11/lib/python3.11/site-packages/django/views/decorators/csrf.py", line 65, in _view_wrapper
    return view_func(request, *args, **kwargs)
           ^^^^^^^^^^^^^^^^^^^^^^^^^^^^^^^^^^^
  File "/home/rashid/.cache/pypoetry/virtualenvs/cropgnosis-p5HYragw-py3.11/lib/python3.11/site-packages/django/views/generic/base.py", line 104, in view
    return self.dispatch(request, *args, **kwargs)
           ^^^^^^^^^^^^^^^^^^^^^^^^^^^^^^^^^^^^^^^
  File "/home/rashid/.cache/pypoetry/virtualenvs/cropgnosis-p5HYragw-py3.11/lib/python3.11/site-packages/rest_framework/views.py", line 509, in dispatch
    response = self.handle_exception(exc)
               ^^^^^^^^^^^^^^^^^^^^^^^^^^
  File "/home/rashid/.cache/pypoetry/virtualenvs/cropgnosis-p5HYragw-py3.11/lib/python3.11/site-packages/rest_framework/views.py", line 469, in handle_exception
    self.raise_uncaught_exception(exc)
  File "/home/rashid/.cache/pypoetry/virtualenvs/cropgnosis-p5HYragw-py3.11/lib/python3.11/site-packages/rest_framework/views.py", line 480, in raise_uncaught_exception
    raise exc
  File "/home/rashid/.cache/pypoetry/virtualenvs/cropgnosis-p5HYragw-py3.11/lib/python3.11/site-packages/rest_framework/views.py", line 506, in dispatch
    response = handler(request, *args, **kwargs)
               ^^^^^^^^^^^^^^^^^^^^^^^^^^^^^^^^^
  File "/home/rashid/.cache/pypoetry/virtualenvs/cropgnosis-p5HYragw-py3.11/lib/python3.11/site-packages/rest_framework/generics.py", line 203, in get
    return self.list(request, *args, **kwargs)
           ^^^^^^^^^^^^^^^^^^^^^^^^^^^^^^^^^^^
  File "/home/rashid/.cache/pypoetry/virtualenvs/cropgnosis-p5HYragw-py3.11/lib/python3.11/site-packages/rest_framework/mixins.py", line 46, in list
    return Response(serializer.data)
                    ^^^^^^^^^^^^^^^
  File "/home/rashid/.cache/pypoetry/virtualenvs/cropgnosis-p5HYragw-py3.11/lib/python3.11/site-packages/rest_framework/serializers.py", line 795, in data
    ret = super().data
          ^^^^^^^^^^^^
  File "/home/rashid/.cache/pypoetry/virtualenvs/cropgnosis-p5HYragw-py3.11/lib/python3.11/site-packages/rest_framework/serializers.py", line 249, in data
    self._data = self.to_representation(self.instance)
                 ^^^^^^^^^^^^^^^^^^^^^^^^^^^^^^^^^^^^^
  File "/home/rashid/.cache/pypoetry/virtualenvs/cropgnosis-p5HYragw-py3.11/lib/python3.11/site-packages/rest_framework/serializers.py", line 713, in to_representation
    return [
           ^
TypeError: 'ModelBase' object is not iterable
[27/Apr/2024 12:04:52] WARNING [django.request:241] Unauthorized: /api/common/mentor-plans
